Workbook

Sheet תוצאות
B1: תוצאות הבחירות | C1: סה"כ קולות | D1: מודד למנדט | E1: מהעודפים | G1: עברה | H1: בטוח בכנסת? | I1: כמה למנדט הבא | M1: המנדטים אחרי | N1: =W6 -> 1.0062844 | O1: מהקולות | P1: שעת עדכון | R1: סדר העודפים | V1: סה"כ בז"ב | W1: 6788804 | AB1: כן
B2: =IF(N17>60, "דיקטטורה", "עם ישראל חי") -> דיקטטורה | C2: =SUM(C3:C42) -> 4763694 | D2: ='נוסחאות'!K2 -> 36213.658 | E2: =SUM(E3:E42) -> 7 | M2: מפלגה | N2: מנדטים | O2: מהעודפים | P2: ='נתונים'!G3 -> 0.71458333 | R2: 1 | S2: =VLOOKUP(R2, 'נוסחאות'!$BE$49:$BI$67, 2, 0) -> ש"ס-יהדות התורה | T2: =VLOOKUP(R2, 'נוסחאות'!$BE$49:$BI$67, 5, 0) -> שס | V2: אחוז הצבעה | W2: 0.7017 | AB2: לא
A3: מחל | B3: הליכוד | C3: =VLOOKUP($A3,'נתונים'!$B$1:$D$50,3,0) -> 1115049 | D3: ='נוסחאות'!D3 -> 32 | E3: =IF(D3=0, "", 'נוסחאות'!F3) -> 2 | F3: =C3/$C$2 -> 0.23407234 | G3: =IF((C3/(SUM($C$3:C$42))>='נוסחאות'!$L$2), "כן", "לא") -> כן | H3: =IF(C3>0.0335*$W$3, "בטוח", "") -> בטוח | I3: =IF(D3>0, 1-('נוסחאות'!H3-(ROUNDDOWN('נוסחאות'!H3,0))), "") -> 0.20915888 | L3: 1 | M3: =VLOOKUP(L3, abc!$A$2:abc!$F$16, 3, false) -> הליכוד | N3: =VLOOKUP(L3, abc!$A$2:abc!$F$16, 5, false) -> 32 | O3: =VLOOKUP(L3, abc!$A$2:abc!$F$16, 6, false) -> 2 | R3: 2 | S3: =VLOOKUP(R3, 'נוסחאות'!$BE$49:$BI$67, 2, 0) -> יש עתיד-המחנה הממלכתי | T3: =VLOOKUP(R3, 'נוסחאות'!$BE$49:$BI$67, 5, 0) -> כן | V3: לכאורה מצביעים | W3: =W1*W2 -> 4763703.8
A4: פה | B4: יש עתיד | C4: =VLOOKUP($A4,'נתונים'!$B$1:$D$50,3,0) -> 847145 | D4: ='נוסחאות'!D4 -> 24 | E4: =IF(D4=0, "", 'נוסחאות'!F4) -> 1 | F4: =C4/$C$2 -> 0.17783363 | G4: =IF((C4/(SUM($C$3:C$42))>='נוסחאות'!$L$2), "כן", "לא") -> כן | H4: =IF(C4>0.0335*$W$3, "בטוח", "") -> בטוח | I4: =IF(D4>0, 1-('נוסחאות'!H4-(ROUNDDOWN('נוסחאות'!H4,0))), "") -> 0.60703063 | L4: 2 | M4: =VLOOKUP(L4, abc!$A$2:abc!$F$16, 3, false) -> יש עתיד | N4: =VLOOKUP(L4, abc!$A$2:abc!$F$16, 5, false) -> 24 | O4: =VLOOKUP(L4, abc!$A$2:abc!$F$16, 6, false) -> 1 | R4: 3 | S4: =VLOOKUP(R4, 'נוסחאות'!$BE$49:$BI$67, 2, 0) -> ליכוד-ציונות דתית | T4: =VLOOKUP(R4, 'נוסחאות'!$BE$49:$BI$67, 5, 0) -> מחל | V4: סה"כ נספרו | W4: ='נתונים'!G1 -> 4793641
A5: ט | B5: הציונות הדתית | C5: =VLOOKUP($A5,'נתונים'!$B$1:$D$50,3,0) -> 516146 | D5: ='נוסחאות'!D5 -> 14 | E5: =IF(D5=0, "", 'נוסחאות'!F5) -> 0 | F5: =C5/$C$2 -> 0.10834995 | G5: =IF((C5/(SUM($C$3:C$42))>='נוסחאות'!$L$2), "כן", "לא") -> כן | H5: =IF(C5>0.0335*$W$3, "בטוח", "") -> בטוח | I5: =IF(D5>0, 1-('נוסחאות'!H5-(ROUNDDOWN('נוסחאות'!H5,0))), "") -> 0.74720081 | L5: 3 | M5: =VLOOKUP(L5, abc!$A$2:abc!$F$16, 3, false) -> הציונות הדתית | N5: =VLOOKUP(L5, abc!$A$2:abc!$F$16, 5, false) -> 14 | O5: =VLOOKUP(L5, abc!$A$2:abc!$F$16, 6, false) -> 0 | R5: 4 | S5: =VLOOKUP(R5, 'נוסחאות'!$BE$49:$BI$67, 2, 0) -> חד"ש-תע"ל | T5: =VLOOKUP(R5, 'נוסחאות'!$BE$49:$BI$67, 5, 0) -> ום | V5: קולות פסולים | W5: ='נתונים'!G2 -> 29947
A6: כן | B6: המחנה הממלכתי | C6: =VLOOKUP($A6,'נתונים'!$B$1:$D$50,3,0) -> 432376 | D6: ='נוסחאות'!D6 -> 12 | E6: =IF(D6=0, "", 'נוסחאות'!F6) -> 1 | F6: =C6/$C$2 -> 0.090764856 | G6: =IF((C6/(SUM($C$3:C$42))>='נוסחאות'!$L$2), "כן", "לא") -> כן | H6: =IF(C6>0.0335*$W$3, "בטוח", "") -> בטוח | I6: =IF(D6>0, 1-('נוסחאות'!H6-(ROUNDDOWN('נוסחאות'!H6,0))), "") -> 0.060416431 | L6: 4 | M6: =VLOOKUP(L6, abc!$A$2:abc!$F$16, 3, false) -> המחנה הממלכתי | N6: =VLOOKUP(L6, abc!$A$2:abc!$F$16, 5, false) -> 12 | O6: =VLOOKUP(L6, abc!$A$2:abc!$F$16, 6, false) -> 1 | R6: 5 | S6: =VLOOKUP(R6, 'נוסחאות'!$BE$49:$BI$67, 2, 0) -> ישראל ביתנו | T6: =VLOOKUP(R6, 'נוסחאות'!$BE$49:$BI$67, 5, 0) -> ל | V6: כמה כיסינו | W6: =W4/W3 -> 1.0062844
A7: שס | B7: ש"ס | C7: =VLOOKUP($A7,'נתונים'!$B$1:$D$50,3,0) -> 392644 | D7: ='נוסחאות'!D7 -> 11 | E7: =IF(D7=0, "", 'נוסחאות'!F7) -> 1 | F7: =C7/$C$2 -> 0.08242427 | G7: =IF((C7/(SUM($C$3:C$42))>='נוסחאות'!$L$2), "כן", "לא") -> כן | H7: =IF(C7>0.0335*$W$3, "בטוח", "") -> בטוח | I7: =IF(D7>0, 1-('נוסחאות'!H7-(ROUNDDOWN('נוסחאות'!H7,0))), "") -> 0.15757153 | L7: 5 | M7: =VLOOKUP(L7, abc!$A$2:abc!$F$16, 3, false) -> ש"ס | N7: =VLOOKUP(L7, abc!$A$2:abc!$F$16, 5, false) -> 11 | O7: =VLOOKUP(L7, abc!$A$2:abc!$F$16, 6, false) -> 1 | R7: 6 | S7: =VLOOKUP(R7, 'נוסחאות'!$BE$49:$BI$67, 2, 0) -> יש עתיד-המחנה הממלכתי | T7: =VLOOKUP(R7, 'נוסחאות'!$BE$49:$BI$67, 5, 0) -> פה
A8: ג | B8: יהדות התורה | C8: =VLOOKUP($A8,'נתונים'!$B$1:$D$50,3,0) -> 280125 | D8: ='נוסחאות'!D8 -> 7 | E8: =IF(D8=0, "", 'נוסחאות'!F8) -> 0 | F8: =C8/$C$2 -> 0.058804155 | G8: =IF((C8/(SUM($C$3:C$42))>='נוסחאות'!$L$2), "כן", "לא") -> כן | H8: =IF(C8>0.0335*$W$3, "בטוח", "") -> בטוח | I8: =IF(D8>0, 1-('נוסחאות'!H8-(ROUNDDOWN('נוסחאות'!H8,0))), "") -> 0.26465889 | L8: 6 | M8: =VLOOKUP(L8, abc!$A$2:abc!$F$16, 3, false) -> יהדות התורה | N8: =VLOOKUP(L8, abc!$A$2:abc!$F$16, 5, false) -> 7 | O8: =VLOOKUP(L8, abc!$A$2:abc!$F$16, 6, false) -> 0 | R8: 7 | S8: =VLOOKUP(R8, 'נוסחאות'!$BE$49:$BI$67, 2, 0) -> ליכוד-ציונות דתית | T8: =VLOOKUP(R8, 'נוסחאות'!$BE$49:$BI$67, 5, 0) -> מחל | V8: לא עברו | W8: =SUMIF(G:G, "לא", C:C) -> 418055
A9: ל | B9: ישראל ביתנו | C9: =VLOOKUP($A9,'נתונים'!$B$1:$D$50,3,0) -> 213655 | D9: ='נוסחאות'!D9 -> 6 | E9: =IF(D9=0, "", 'נוסחאות'!F9) -> 1 | F9: =C9/$C$2 -> 0.044850698 | G9: =IF((C9/(SUM($C$3:C$42))>='נוסחאות'!$L$2), "כן", "לא") -> כן | H9: =IF(C9>0.0335*$W$3, "בטוח", "") -> בטוח | I9: =IF(D9>0, 1-('נוסחאות'!H9-(ROUNDDOWN('נוסחאות'!H9,0))), "") -> 0.1001542 | L9: 7 | M9: =VLOOKUP(L9, abc!$A$2:abc!$F$16, 3, false) -> ישראל ביתנו | N9: =VLOOKUP(L9, abc!$A$2:abc!$F$16, 5, false) -> 6 | O9: =VLOOKUP(L9, abc!$A$2:abc!$F$16, 6, false) -> 1 | R9: 8 | S9: =VLOOKUP(R9, 'נוסחאות'!$BE$49:$BI$67, 2, 0) -> ש"ס-יהדות התורה | T9: =VLOOKUP(R9, 'נוסחאות'!$BE$49:$BI$67, 5, 0) -> ג | V9: הלכו לפח | W9: =W8/W3 -> 0.087758396
A10: אמת | B10: העבודה | C10: =VLOOKUP($A10,'נתונים'!$B$1:$D$50,3,0) -> 175922 | D10: ='נוסחאות'!D10 -> 4 | E10: =IF(D10=0, "", 'נוסחאות'!F10) -> 0 | F10: =C10/$C$2 -> 0.036929744 | G10: =IF((C10/(SUM($C$3:C$42))>='נוסחאות'!$L$2), "כן", "לא") -> כן | H10: =IF(C10>0.0335*$W$3, "בטוח", "") -> בטוח | I10: =IF(D10>0, 1-('נוסחאות'!H10-(ROUNDDOWN('נוסחאות'!H10,0))), "") -> 0.14210914 | L10: 8 | M10: =VLOOKUP(L10, abc!$A$2:abc!$F$16, 3, false) -> רע"ם | N10: =VLOOKUP(L10, abc!$A$2:abc!$F$16, 5, false) -> 5 | O10: =VLOOKUP(L10, abc!$A$2:abc!$F$16, 6, false) -> 0 | R10: 9 | S10: =VLOOKUP(R10, 'נוסחאות'!$BE$49:$BI$67, 2, 0) -> העבודה-מרצ | T10: =VLOOKUP(R10, 'נוסחאות'!$BE$49:$BI$67, 5, 0) -> אמת | V10: במנדטים | W10: =W8/D2 -> 11.544125
A11: מרצ | B11: מרצ | C11: =VLOOKUP($A11,'נתונים'!$B$1:$D$50,3,0) -> 150696 | D11: ='נוסחאות'!D11 -> 0 | E11: =IF(D11=0, "", 'נוסחאות'!F11) | F11: =C11/$C$2 -> 0.031634274 | G11: =IF((C11/(SUM($C$3:C$42))>='נוסחאות'!$L$2), "כן", "לא") -> לא | H11: =IF(C11>0.0335*$W$3, "בטוח", "") | I11: =IF(D11>0, 1-('נוסחאות'!H11-(ROUNDDOWN('נוסחאות'!H11,0))), "") | L11: 9 | M11: =VLOOKUP(L11, abc!$A$2:abc!$F$16, 3, false) -> חד"ש-תע"ל | N11: =VLOOKUP(L11, abc!$A$2:abc!$F$16, 5, false) -> 5 | O11: =VLOOKUP(L11, abc!$A$2:abc!$F$16, 6, false) -> 1 | R11: 10 | S11: =VLOOKUP(R11, 'נוסחאות'!$BE$49:$BI$67, 2, 0) -> ליכוד-ציונות דתית | T11: =VLOOKUP(R11, 'נוסחאות'!$BE$49:$BI$67, 5, 0) -> ט
A12: ום | B12: חד"ש-תע"ל | C12: =VLOOKUP($A12,'נתונים'!$B$1:$D$50,3,0) -> 178661 | D12: ='נוסחאות'!D12 -> 5 | E12: =IF(D12=0, "", 'נוסחאות'!F12) -> 1 | F12: =C12/$C$2 -> 0.037504718 | G12: =IF((C12/(SUM($C$3:C$42))>='נוסחאות'!$L$2), "כן", "לא") -> כן | H12: =IF(C12>0.0335*$W$3, "בטוח", "") -> בטוח | I12: =IF(D12>0, 1-('נוסחאות'!H12-(ROUNDDOWN('נוסחאות'!H12,0))), "") -> 0.066474689 | L12: 10 | M12: =VLOOKUP(L12, abc!$A$2:abc!$F$16, 3, false) -> העבודה | N12: =VLOOKUP(L12, abc!$A$2:abc!$F$16, 5, false) -> 4 | O12: =VLOOKUP(L12, abc!$A$2:abc!$F$16, 6, false) -> 0
A13: עם | B13: רע"ם | C13: =VLOOKUP($A13,'נתונים'!$B$1:$D$50,3,0) -> 193916 | D13: ='נוסחאות'!D13 -> 5 | E13: =IF(D13=0, "", 'נוסחאות'!F13) -> 0 | F13: =C13/$C$2 -> 0.040707065 | G13: =IF((C13/(SUM($C$3:C$42))>='נוסחאות'!$L$2), "כן", "לא") -> כן | H13: =IF(C13>0.0335*$W$3, "בטוח", "") -> בטוח | I13: =IF(D13>0, 1-('נוסחאות'!H13-(ROUNDDOWN('נוסחאות'!H13,0))), "") -> 0.64522479 | L13: 11 | M13: =VLOOKUP(L13, abc!$A$2:abc!$F$16, 3, false) -> מרצ | N13: =VLOOKUP(L13, abc!$A$2:abc!$F$16, 5, false) -> 0 | O13: =VLOOKUP(L13, abc!$A$2:abc!$F$16, 6, false) -> 0
A14: ד | B14: בל"ד | C14: =VLOOKUP($A14,'נתונים'!$B$1:$D$50,3,0) -> 138093 | D14: ='נוסחאות'!D14 -> 0 | E14: =IF(D14=0, "", 'נוסחאות'!F14) | F14: =C14/$C$2 -> 0.028988638 | G14: =IF((C14/(SUM($C$3:C$42))>='נוסחאות'!$L$2), "כן", "לא") -> לא | H14: =IF(C14>0.0335*$W$3, "בטוח", "") | I14: =IF(D14>0, 1-('נוסחאות'!H14-(ROUNDDOWN('נוסחאות'!H14,0))), "") | L14: 12 | M14: =iferror(VLOOKUP(L14, abc!$A$2:abc!$F$16, 3, false), "") -> בל"ד | N14: =VLOOKUP(L14, abc!$A$2:abc!$F$16, 5, false) -> 0 | O14: =VLOOKUP(L14, abc!$A$2:abc!$F$16, 6, false) -> 0
A15: ב | B15: הבית היהודי | C15: =VLOOKUP($A15,'נתונים'!$B$1:$D$50,3,0) -> 56793 | D15: ='נוסחאות'!D15 -> 0 | E15: =IF(D15=0, "", 'נוסחאות'!F15) | F15: =C15/$C$2 -> 0.01192205 | G15: =IF((C15/(SUM($C$3:C$42))>='נוסחאות'!$L$2), "כן", "לא") -> לא | H15: =IF(C15>0.0335*$W$3, "בטוח", "") | I15: =IF(D15>0, 1-('נוסחאות'!H15-(ROUNDDOWN('נוסחאות'!H15,0))), "") | L15: 13 | M15: =VLOOKUP(L15, abc!$A$2:abc!$F$16, 3, false) -> הבית היהודי | N15: =VLOOKUP(L15, abc!$A$2:abc!$F$16, 5, false) -> 0 | O15: =VLOOKUP(L15, abc!$A$2:abc!$F$16, 6, false) -> 0
A16: יז | B16: הכלכלית החדשה | C16: =VLOOKUP($A16,'נתונים'!$B$1:$D$50,3,0) -> 13911 | D16: ='נוסחאות'!D16 -> 0 | E16: =IF(D16=0, "", 'נוסחאות'!F16) | F16: =C16/$C$2 -> 0.0029202128 | G16: =IF((C16/(SUM($C$3:C$42))>='נוסחאות'!$L$2), "כן", "לא") -> לא | H16: =IF(C16>0.0335*$W$3, "בטוח", "") | I16: =IF(D16>0, 1-('נוסחאות'!H16-(ROUNDDOWN('נוסחאות'!H16,0))), "")
A17: י | B17: ישראל חופשית | C17: =VLOOKUP($A17,'נתונים'!$B$1:$D$50,3,0) -> 1156 | D17: ='נוסחאות'!D17 -> 0 | E17: =IF(D17=0, "", 'נוסחאות'!F17) | F17: =C17/$C$2 -> 0.00024266882 | G17: =IF((C17/(SUM($C$3:C$42))>='נוסחאות'!$L$2), "כן", "לא") -> לא | H17: =IF(C17>0.0335*$W$3, "בטוח", "") | I17: =IF(D17>0, 1-('נוסחאות'!H17-(ROUNDDOWN('נוסחאות'!H17,0))), "") | L17: גוש ביבי | N17: =D3+D5+D7+D8 -> 64
A18: צ | B18: צעירים בוערים | C18: =VLOOKUP($A18,'נתונים'!$B$1:$D$50,3,0) -> 8794 | D18: ='נוסחאות'!D18 -> 0 | E18: =IF(D18=0, "", 'נוסחאות'!F18) | F18: =C18/$C$2 -> 0.0018460464 | G18: =IF((C18/(SUM($C$3:C$42))>='נוסחאות'!$L$2), "כן", "לא") -> לא | H18: =IF(C18>0.0335*$W$3, "בטוח", "") | I18: =IF(D18>0, 1-('נוסחאות'!H18-(ROUNDDOWN('נוסחאות'!H18,0))), "") | L18: הקואליציה היוצאת | N18: =D4+D6+D9+D10+D11+D13 -> 51 | V18: בניית ממשלה | W18: =SUMIF(X19:X29, "כן", W19:W29)+W30 -> 64
A19: אצ | B19: חופש כלכלי | C19: =VLOOKUP($A19,'נתונים'!$B$1:$D$50,3,0) -> 15817 | D19: ='נוסחאות'!D19 -> 0 | E19: =IF(D19=0, "", 'נוסחאות'!F19) | F19: =C19/$C$2 -> 0.0033203224 | G19: =IF((C19/(SUM($C$3:C$42))>='נוסחאות'!$L$2), "כן", "לא") -> לא | H19: =IF(C19>0.0335*$W$3, "בטוח", "") | L19: ביבי, חרדים, גנץ | N19: =D3+D6+D7+D8 -> 62 | Q19: מדגמים | V19: =M3 -> הליכוד | W19: =N3 -> 32 | X19: כן
A20: ז | B20: שחר כח חברתי | C20: =VLOOKUP($A20,'נתונים'!$B$1:$D$50,3,0) -> 530 | D20: ='נוסחאות'!D20 -> 0 | E20: =IF(D20=0, "", 'נוסחאות'!F20) | F20: =C20/$C$2 -> 0.0001112582 | G20: =IF((C20/(SUM($C$3:C$42))>='נוסחאות'!$L$2), "כן", "לא") -> לא | H20: =IF(C20>0.0335*$W$3, "בטוח", "") | L20: חוסם לביבי עם חד"ש | N20: =N18+D12 -> 56 | R20: 12 | S20: 13 | T20: 11 | V20: =M4 -> יש עתיד | W20: =N4 -> 24 | X20: לא
A21: זך | B21: קמ"ה | C21: =VLOOKUP($A21,'נתונים'!$B$1:$D$50,3,0) -> 205 | D21: ='נוסחאות'!D21 -> 0 | E21: =IF(D21=0, "", 'נוסחאות'!F21) | F21: =C21/$C$2 -> 4.303383e-05 | G21: =IF((C21/(SUM($C$3:C$42))>='נוסחאות'!$L$2), "כן", "לא") -> לא | H21: =IF(C21>0.0335*$W$3, "בטוח", "") | Q21: גוש ביבי | R21: =R24+R26+R28+R29 -> 62 | S21: =S24+S26+S28+S29 -> 62 | T21: =T24+T26+T28+T29 -> 62 | V21: =M5 -> הציונות הדתית | W21: =N5 -> 14 | X21: כן
A22: זנ | B22: כח להשפיע | C22: =VLOOKUP($A22,'נתונים'!$B$1:$D$50,3,0) -> 152 | D22: ='נוסחאות'!D22 -> 0 | E22: =IF(D22=0, "", 'נוסחאות'!F22) | F22: =C22/$C$2 -> 3.1908011e-05 | G22: =IF((C22/(SUM($C$3:C$42))>='נוסחאות'!$L$2), "כן", "לא") -> לא | H22: =IF(C22>0.0335*$W$3, "בטוח", "") | Q22: הקואליציה | R22: =R25+R27+R30+R31+R32+R34 -> 53 | S22: =S25+S27+S30+S31+S32+S34 -> 53 | T22: =T25+T27+T30+T31+T32+T34 -> 54 | V22: =M6 -> המחנה הממלכתי | W22: =N6 -> 12 | X22: לא
A23: זץ | B23: צומת | C23: =VLOOKUP($A23,'נתונים'!$B$1:$D$50,3,0) -> 377 | D23: ='נוסחאות'!D23 -> 0 | E23: =IF(D23=0, "", 'נוסחאות'!F23) | F23: =C23/$C$2 -> 7.9140264e-05 | G23: =IF((C23/(SUM($C$3:C$42))>='נוסחאות'!$L$2), "כן", "לא") -> לא | H23: =IF(C23>0.0335*$W$3, "בטוח", "") | L23: ="אחוז החסימה המשוער:"&" "&ROUNDDOWN(W3*0.0325,0) -> אחוז החסימה המשוער: 154820 | Q23: חדש | R23: =R33 -> 5 | S23: =S33 -> 5 | T23: =T33 -> 4 | V23: =M7 -> ש"ס | W23: =N7 -> 11 | X23: כן
A24: ינ | B24: איחוד בני הברית | C24: =VLOOKUP($A24,'נתונים'!$B$1:$D$50,3,0) -> 234 | D24: ='נוסחאות'!D24 -> 0 | E24: =IF(D24=0, "", 'נוסחאות'!F24) | F24: =C24/$C$2 -> 4.9121543e-05 | G24: =IF((C24/(SUM($C$3:C$42))>='נוסחאות'!$L$2), "כן", "לא") -> לא | H24: =IF(C24>0.0335*$W$3, "בטוח", "") | L24: על סף אחוז החסימה | N24: =roundup(SUM(C3:C50)*3.25%,0) -> 154821 | Q24: הליכוד | R24: 31 | S24: 32 | T24: 30 | V24: =M8 -> יהדות התורה | W24: =N8 -> 7 | X24: כן
A25: יץ | B25: צו השעה | C25: =VLOOKUP($A25,'נתונים'!$B$1:$D$50,3,0) -> 265 | D25: ='נוסחאות'!D25 -> 0 | E25: =IF(D25=0, "", 'נוסחאות'!F25) | F25: =C25/$C$2 -> 5.5629098e-05 | G25: =IF((C25/(SUM($C$3:C$42))>='נוסחאות'!$L$2), "כן", "לא") -> לא | H25: =IF(C25>0.0335*$W$3, "בטוח", "") | L25: מפלגה | M25: בקולות | N25: באחוזים | Q25: יש עתיד | R25: 23 | S25: 23 | T25: 23 | V25: =M9 -> ישראל ביתנו | W25: =N9 -> 6 | X25: לא
A26: יק | B26: הגוש התנכ"י | C26: =VLOOKUP($A26,'נתונים'!$B$1:$D$50,3,0) -> 425 | D26: ='נוסחאות'!D26 -> 0 | E26: =IF(D26=0, "", 'נוסחאות'!F26) | F26: =C26/$C$2 -> 8.9216478e-05 | G26: =IF((C26/(SUM($C$3:C$42))>='נוסחאות'!$L$2), "כן", "לא") -> לא | H26: =IF(C26>0.0335*$W$3, "בטוח", "") | K26: 1 | L26: =VLOOKUP(K26, abc!$N$2:abc!$R$9, 2, false) -> ישראל ביתנו | M26: =VLOOKUP(K26, abc!$N$2:abc!$R$9, 4, false) -> 58834 | N26: =VLOOKUP(K26, abc!$N$2:abc!$R$9, 5, false) -> 1.2350698 | Q26: הציונות הדתית | R26: 14 | S26: 13 | T26: 15 | V26: =M10 -> רע"ם | W26: =N10 -> 5 | X26: לא
A27: ך | B27: אני ואתה | C27: =VLOOKUP($A27,'נתונים'!$B$1:$D$50,3,0) -> 1321 | D27: ='נוסחאות'!D27 -> 0 | E27: =IF(D27=0, "", 'נוסחאות'!F27) | F27: =C27/$C$2 -> 0.00027730581 | G27: =IF((C27/(SUM($C$3:C$42))>='נוסחאות'!$L$2), "כן", "לא") -> לא | H27: =IF(C27>0.0335*$W$3, "בטוח", "") | K27: 2 | L27: =VLOOKUP(K27, abc!$N$2:abc!$R$9, 2, false) -> רע"ם | M27: =VLOOKUP(K27, abc!$N$2:abc!$R$9, 4, false) -> 39095 | N27: =VLOOKUP(K27, abc!$N$2:abc!$R$9, 5, false) -> 0.82070647 | Q27: הממלכתי | R27: 11 | S27: 11 | T27: 12 | V27: =M11 -> חד"ש-תע"ל | W27: =N11 -> 5
A28: נז | B28: כבוד האדם | C28: =VLOOKUP($A28,'נתונים'!$B$1:$D$50,3,0) -> 533 | D28: ='נוסחאות'!D28 -> 0 | E28: =IF(D28=0, "", 'נוסחאות'!F28) | F28: =C28/$C$2 -> 0.00011188796 | G28: =IF((C28/(SUM($C$3:C$42))>='נוסחאות'!$L$2), "כן", "לא") -> לא | H28: =IF(C28>0.0335*$W$3, "בטוח", "") | K28: 3 | L28: =VLOOKUP(K28, abc!$N$2:abc!$R$9, 2, false) -> חד"ש-תע"ל | M28: =VLOOKUP(K28, abc!$N$2:abc!$R$9, 4, false) -> 23840 | N28: =VLOOKUP(K28, abc!$N$2:abc!$R$9, 5, false) -> 0.5004718 | Q28: ש"ס | R28: 10 | S28: 10 | T28: 10 | V28: =M12 -> העבודה | W28: =N12 -> 4
A29: ני | B29: נתיב | C29: =VLOOKUP($A29,'נתונים'!$B$1:$D$50,3,0) -> 1344 | D29: ='נוסחאות'!D29 -> 0 | E29: =IF(D29=0, "", 'נוסחאות'!F29) | F29: =C29/$C$2 -> 0.00028213399 | G29: =IF((C29/(SUM($C$3:C$42))>='נוסחאות'!$L$2), "כן", "לא") -> לא | H29: =IF(C29>0.0335*$W$3, "בטוח", "") | I29: =IF(D29>0, 1-('נוסחאות'!H29-(ROUNDDOWN('נוסחאות'!H29,0))), "") | K29: 4 | L29: =VLOOKUP(K29, abc!$N$2:abc!$R$9, 2, false) -> העבודה | M29: =VLOOKUP(K29, abc!$N$2:abc!$R$9, 4, false) -> 21101 | N29: =VLOOKUP(K29, abc!$N$2:abc!$R$9, 5, false) -> 0.4429744 | Q29: יהדות התורה | R29: 7 | S29: 7 | T29: 7 | V29: =M13 -> מרצ | W29: =N13 -> 0 | X29: לא
A30: נף | B30: שמע | C30: =VLOOKUP($A30,'נתונים'!$B$1:$D$50,3,0) -> 256 | D30: ='נוסחאות'!D30 -> 0 | E30: =IF(D30=0, "", 'נוסחאות'!F30) | F30: =C30/$C$2 -> 5.3739808e-05 | G30: =IF((C30/(SUM($C$3:C$42))>='נוסחאות'!$L$2), "כן", "לא") -> לא | H30: =IF(C30>0.0335*$W$3, "בטוח", "") | K30: 5 | L30: =VLOOKUP(K30, abc!$N$2:abc!$R$9, 2, false) -> מרצ | M30: =VLOOKUP(K30, abc!$N$2:abc!$R$9, 4, false) -> -4125 | N30: =VLOOKUP(K30, abc!$N$2:abc!$R$9, 5, false) -> -0.086572626 | Q30: ישראל ביתנו | R30: 5 | S30: 6 | T30: 5 | V30: עריקים
A31: נץ | B31: העצמאים החדשים | C31: =VLOOKUP($A31,'נתונים'!$B$1:$D$50,3,0) -> 1018 | D31: ='נוסחאות'!D31 -> 0 | E31: =IF(D31=0, "", 'נוסחאות'!F31) | F31: =C31/$C$2 -> 0.0002136997 | G31: =IF((C31/(SUM($C$3:C$42))>='נוסחאות'!$L$2), "כן", "לא") -> לא | H31: =IF(C31>0.0335*$W$3, "בטוח", "") | K31: 6 | L31: =VLOOKUP(K31, abc!$N$2:abc!$R$9, 2, false) -> בל"ד | M31: =VLOOKUP(K31, abc!$N$2:abc!$R$9, 4, false) -> -16728 | N31: =VLOOKUP(K31, abc!$N$2:abc!$R$9, 5, false) -> -0.35113622 | Q31: העבודה | R31: 5 | S31: 5 | T31: 5
A32: נק | B32: יש כיוון | C32: =VLOOKUP($A32,'נתונים'!$B$1:$D$50,3,0) -> 1213 | D32: ='נוסחאות'!D32 -> 0 | E32: =IF(D32=0, "", 'נוסחאות'!F32) | F32: =C32/$C$2 -> 0.00025463432 | G32: =IF((C32/(SUM($C$3:C$42))>='נוסחאות'!$L$2), "כן", "לא") -> לא | H32: =IF(C32>0.0335*$W$3, "בטוח", "") | K32: 7 | L32: =VLOOKUP(K32, abc!$N$2:abc!$R$9, 2, false) -> הבית היהודי | M32: =VLOOKUP(K32, abc!$N$2:abc!$R$9, 4, false) -> -98028 | N32: =VLOOKUP(K32, abc!$N$2:abc!$R$9, 5, false) -> -2.057795 | Q32: מרצ | R32: 4 | S32: 4 | T32: 4
A33: נר | B33: אנחנו | C33: =VLOOKUP($A33,'נתונים'!$B$1:$D$50,3,0) -> 413 | D33: ='נוסחאות'!D33 -> 0 | E33: =IF(D33=0, "", 'נוסחאות'!F33) | F33: =C33/$C$2 -> 8.6697424e-05 | G33: =IF((C33/(SUM($C$3:C$42))>='נוסחאות'!$L$2), "כן", "לא") -> לא | H33: =IF(C33>0.0335*$W$3, "בטוח", "") | Q33: חד"ש-תע"ל | R33: 5 | S33: 5 | T33: 4
A34: ף | B34: הפיראטים | C34: =VLOOKUP($A34,'נתונים'!$B$1:$D$50,3,0) -> 1728 | D34: ='נוסחאות'!D34 -> 0 | E34: =IF(D34=0, "", 'נוסחאות'!F34) | F34: =C34/$C$2 -> 0.0003627437 | G34: =IF((C34/(SUM($C$3:C$42))>='נוסחאות'!$L$2), "כן", "לא") -> לא | H34: =IF(C34>0.0335*$W$3, "בטוח", "") | Q34: רע"ם | R34: 5 | S34: 4 | T34: 5
A35: ץ | B35: מנהיגות חברתית | C35: 982 | D35: ='נוסחאות'!D35 -> 0 | E35: =IF(D35=0, "", 'נוסחאות'!F35) | F35: =C35/$C$2 -> 0.00020614254 | G35: =IF((C35/(SUM($C$3:C$42))>='נוסחאות'!$L$2), "כן", "לא") -> לא | H35: =IF(C35>0.0335*$W$3, "בטוח", "") | I35: לעדכן ידנית!! | L35: תוספת | M35: סהכ קולות | N35: מרצ | Q35: בל"ד | R35: 0 | S35: 0 | T35: 0
A36: ק | B36: קול הסביבה והחי | C36: =VLOOKUP($A36,'נתונים'!$B$1:$D$50,3,0) -> 1619 | D36: ='נוסחאות'!D36 -> 0 | E36: =IF(D36=0, "", 'נוסחאות'!F36) | F36: =C36/$C$2 -> 0.0003398623 | G36: =IF((C36/(SUM($C$3:C$42))>='נוסחאות'!$L$2), "כן", "לא") -> לא | H36: =IF(C36>0.0335*$W$3, "בטוח", "") | L36: 0 | M36: =C2 -> 4763694 | N36: =C11 -> 150696 | O36: =N36/M36 -> 0.031634274 | Q36: הבית היהודי | R36: 0 | S36: 0 | T36: 0
A37: קי | B37: הלב היהודי | C37: =VLOOKUP($A37,'נתונים'!$B$1:$D$50,3,0) -> 412 | D37: ='נוסחאות'!D37 -> 0 | E37: =IF(D37=0, "", 'נוסחאות'!F37) | F37: =C37/$C$2 -> 8.6487503e-05 | G37: =IF((C37/(SUM($C$3:C$42))>='נוסחאות'!$L$2), "כן", "לא") -> לא | H37: =IF(C37>0.0335*$W$3, "בטוח", "") | L37: 4435 | M37: =M36+$L$37 -> 4768129 | N37: =N36+$L$37 -> 155131 | O37: =if(N37/M37>0.0325, "כן", "לא") -> כן | R37: =SUM(R24:R36) -> 120 | S37: =SUM(S24:S36) -> 120 | T37: =SUM(T24:T36) -> 120
A38: קך | B38: סדר חדש | C38: =VLOOKUP($A38,'נתונים'!$B$1:$D$50,3,0) -> 1078 | D38: ='נוסחאות'!D38 -> 0 | E38: =IF(D38=0, "", 'נוסחאות'!F38) | F38: =C38/$C$2 -> 0.00022629497 | G38: =IF((C38/(SUM($C$3:C$42))>='נוסחאות'!$L$2), "כן", "לא") -> לא | H38: =IF(C38>0.0335*$W$3, "בטוח", "") | Q38: מחל שס ג כן | R38: =R24+R27+R28+R29 -> 59 | S38: =S24+S27+S28+S29 -> 60 | T38: =T24+T27+T28+T29 -> 59
A39: קנ | B39: כל קול קובע | C39: =VLOOKUP($A39,'נתונים'!$B$1:$D$50,3,0) -> 1292 | D39: ='נוסחאות'!D39 -> 0 | E39: =IF(D39=0, "", 'נוסחאות'!F39) | F39: =C39/$C$2 -> 0.00027121809 | G39: =IF((C39/(SUM($C$3:C$42))>='נוסחאות'!$L$2), "כן", "לא") -> לא | H39: =IF(C39>0.0335*$W$3, "בטוח", "") | Q39: קואליציה+חדש | R39: =R22+R33 -> 58 | S39: =S22+S33 -> 58 | T39: =T22+T33 -> 58
A40: קץ | B40: באומץ בשבילך | C40: =VLOOKUP($A40,'נתונים'!$B$1:$D$50,3,0) -> 14781 | D40: ='נוסחאות'!D40 -> 0 | E40: =IF(D40=0, "", 'נוסחאות'!F40) | F40: =C40/$C$2 -> 0.0031028441 | G40: =IF((C40/(SUM($C$3:C$42))>='נוסחאות'!$L$2), "כן", "לא") -> לא | H40: =IF(C40>0.0335*$W$3, "בטוח", "") | Q40: שמאל יהודי | R40: =R22-R34 -> 48 | S40: =S22-S34 -> 49 | T40: =T22-T34 -> 49
...

Sheet נתונים
A1: הליכוד בהנהגת בנימין נתניהו לראשות הממשלה | B1: מחל | C1: 0.2341 | D1: 1115049 | F1: קולות שהוזנו | G1: 4793641
A2: יש עתיד בראשות יאיר לפיד לראשות הממשלה | B2: פה | C2: 0.1778 | D2: 847145 | F2: קולות פסולים | G2: 29947
A3: הציונות הדתית בראשות בצלאל סמוטריץ` ועוצמה יהודית | B3: ט | C3: 0.1083 | D3: 516146 | F3: שעת עדכון | G3: 0.71458333
A4: המחנה הממלכתי בהנהגת בני גנץ לראשות הממשלה | B4: כן | C4: 0.0908 | D4: 432376
A5: התאחדות הספרדים שומרי תורה תנועתו של מרן הרב עובדי | B5: שס | C5: 0.0824 | D5: 392644
A6: יהדות התורה והשבת אגודת ישראל - דגל התורה | B6: ג | C6: 0.0588 | D6: 280125
A7: ישראל ביתנו בראשות אביגדור ליברמן | B7: ל | C7: 0.0449 | D7: 213655
A8: הרשימה הערבית המאוחדת | B8: עם | C8: 0.0407 | D8: 193916
A9: חד"ש תע"ל בראשות איימן עודה ואחמד טיבי | B9: ום | C9: 0.0375 | D9: 178661
A10: מפלגת העבודה בראשות מרב מיכאלי | B10: אמת | C10: 0.0369 | D10: 175922
A11: מרצ השמאל של ישראל בראשות זהבה גלאון | B11: מרצ | C11: 0.0316 | D11: 150696
A12: בל"ד - אלתג`מוע אלווטני אלדמוקרטי בראשות סמי אבו ש | B12: ד | C12: 0.029 | D12: 138093
A13: הבית היהודי בראשות איילת שקד | B13: ב | C13: 0.0119 | D13: 56793
A14: חופש כלכלי בראשות אביר קארה | B14: אצ | C14: 0.0033 | D14: 15817
A15: באומץ בשבילך | B15: קץ | C15: 0.0031 | D15: 14781
... A40: כח להשפיע בראשות בני אלבז | B40: זנ | C40: 0 | D40: 152

Sheet נוסחאות
A1: פתק | B1: מפלגות שעברו | C1: קולות | E1: מנדט 1 | F1: עודפים | G1: עברה | H1: מנדטים 1 | I1: כמה חסר | J1: עודפים | K1: מודד למנדט | L1: חסימה | W1: איחוד | Y1: מודדים מאוחד | AD1: דירוג מאוחד | AI1: מודד רשימה 1 | AN1: מודד רשימה 2 | AS1: רשימה 1 | AX1: רשימה 2
B2: =COUNTIF(G3:G41, "כן") -> 10 | C2: =SUM(C3:C41) -> 4762025 | H2: =SUM(H3:H41) -> 120 | J2: =120-SUM(E3:E20) -> 7 | K2: =(SUMIFS(C$3:C$32,G$3:G$32,"כן"))/120 -> 36213.658 | L2: 0.0325 | Q2: תוספת | U2: תוספת | V2: תוספת סהכ | W2: קולות | X2: מנדטים | Y2: 1 | Z2: 2 | AA2: 3 | AB2: 4 | AC2: 5 | AD2: דירוג 1 | AE2: דירוג 2 | AF2: דירוג 3 | AG2: דירוג 4 | AH2: דירוג 5 | AI2: 1 | AJ2: 2 | AK2: 3 | AL2: 4 | AM2: 5 | AN2: 1 | AO2: 2 | AP2: 3 | AQ2: 4 | AR2: 5 | AS2: דירוג 1 | AT2: דירוג 2 | AU2: דירוג 3 | AV2: דירוג 4 | AW2: דירוג 5 | AX2: דירוג 1 | AY2: דירוג 2 | AZ2: דירוג 3 | BA2: דירוג 4 | BB2: דירוג 5
A3: מחל | B3: הליכוד | C3: ='תוצאות'!C3 -> 1115049 | D3: =E3+F3 -> 32 | E3: =ROUNDDOWN(H3,0) -> 30 | F3: =Q3 -> 2 | G3: =IF((C3/(SUM($C$3:C$41))>=$L$2), "כן", "לא") -> כן | H3: =IF(G3="כן", (C3/$K$2), 0) -> 30.790841 | I3: =IF(G3="כן", $K$2*(E3+1)-C3, "") -> 7574.4083 | N3: מחל | O3: =C3 -> 1115049 | P3: =E3 -> 30 | Q3: =COUNTIF(AS3:AW3,"<="&V3) -> 2 | R3: ט | S3: =C5 -> 516146 | T3: =E5 -> 14 | U3: =COUNTIF(AX3:BB3,"<="&V3) -> 0 | V3: =COUNTIF(AD3:AH3,"<="&J$2) -> 2 | W3: =IF(P3>0, IF(T3>0, O3+S3, O3), IF(T3>0, S3, 0)) -> 1631195 | X3: =P3+T3 -> 44 | Y3: =IF(X3>0, $W3/($X3+Y$2), 0) -> 36248.778 | Z3: =IF(Y3>0, $W3/($X3+Z$2), 0) -> 35460.761 | AA3: =IF(Z3>0, $W3/($X3+AA$2), 0) -> 34706.277 | AB3: =IF(AA3>0, $W3/($X3+AB$2), 0) -> 33983.229 | AC3: =IF(AB3>0, $W3/($X3+AC$2), 0) -> 33289.694 | AD3: =RANK(Y3, $Y$3:$AC$29) -> 3 | AE3: =RANK(Z3, $Y$3:$AC$29) -> 7 | AF3: =RANK(AA3, $Y$3:$AC$29) -> 10 | AG3: =RANK(AB3, $Y$3:$AC$29) -> 12 | AH3: =RANK(AC3, $Y$3:$AC$29) -> 15 | AI3: =IF($P3>0, $O3/($P3+AI$2), 0) -> 35969.323 | AJ3: =IF($P3>0, $O3/($P3+AJ$2), 0) -> 34845.281 | AK3: =IF($P3>0, $O3/($P3+AK$2), 0) -> 33789.364 | AL3: =IF($P3>0, $O3/($P3+AL$2), 0) -> 32795.559 | AM3: =IF($P3>0, $O3/($P3+AM$2), 0) -> 31858.543 | AN3: =IF($T3>0, $S3/($T3+AN$2), 0) -> 34409.733 | AO3: =IF($T3>0, $S3/($T3+AO$2), 0) -> 32259.125 | AP3: =IF($T3>0, $S3/($T3+AP$2), 0) -> 30361.529 | AQ3: =IF($T3>0, $S3/($T3+AQ$2), 0) -> 28674.778 | AR3: =IF($T3>0, $S3/($T3+AR$2), 0) -> 27165.579 | AS3: =RANK(AI3, $AI3:$AR3) -> 1 | AT3: =RANK(AJ3, $AI3:$AR3) -> 2 | AU3: =RANK(AK3, $AI3:$AR3) -> 4 | AV3: =RANK(AL3, $AI3:$AR3) -> 5 | AW3: =RANK(AM3, $AI3:$AR3) -> 7 | AX3: =RANK(AN3, $AI3:$AR3) -> 3 | AY3: =RANK(AO3, $AI3:$AR3) -> 6 | AZ3: =RANK(AP3, $AI3:$AR3) -> 8 | ... BB3: =RANK(AR3, $AI3:$AR3) -> 10 | BE3: מחל | BF3: ט | BI3: ליכוד-ציונות דתית | BJ3: 1 | BK3: =BJ3&BI3 -> 1ליכוד-ציונות דתית | BL3: =if(BJ3=AS3, $BE3, IF(BJ3=AT3, $BE3, IF(BJ3=AX3, BF3))) -> מחל | BO3: 2 | BP3: =if(AT3=BO3, $BE3, $BF3) -> מחל
A4: פה | B4: יש עתיד | C4: ='תוצאות'!C4 -> 847145 | D4: =E4+F4 -> 24 | E4: =ROUNDDOWN(H4,0) -> 23 | F4: =Q4 -> 1 | G4: =IF((C4/(SUM($C$3:C$41))>=$L$2), "כן", "לא") -> כן | H4: =IF(G4="כן", (C4/$K$2), 0) -> 23.392969 | I4: =IF(G4="כן", $K$2*(E4+1)-C4, "") -> 21982.8 | N4: פה | O4: =C4 -> 847145 | P4: =E4 -> 23 | Q4: =COUNTIF(AS4:AW4,"<="&V4) -> 1 | R4: כן | S4: =C6 -> 432376 | T4: =E6 -> 11 | U4: =COUNTIF(AX4:BB4,"<="&V4) -> 1 | V4: =COUNTIF(AD4:AH4,"<="&J$2) -> 2 | W4: =IF(P4>0, IF(T4>0, O4+S4, O4), IF(T4>0, S4, 0)) -> 1279521 | X4: =P4+T4 -> 34 | Y4: =IF(X4>0, $W4/($X4+Y$2), 0) -> 36557.743 | Z4: =IF(Y4>0, $W4/($X4+Z$2), 0) -> 35542.25 | AA4: =IF(Z4>0, $W4/($X4+AA$2), 0) -> 34581.649 | AB4: =IF(AA4>0, $W4/($X4+AB$2), 0) -> 33671.605 | AC4: =IF(AB4>0, $W4/($X4+AC$2), 0) -> 32808.231 | AD4: =RANK(Y4, $Y$3:$AC$29) -> 2 | AE4: =RANK(Z4, $Y$3:$AC$29) -> 6 | AF4: =RANK(AA4, $Y$3:$AC$29) -> 11 | AG4: =RANK(AB4, $Y$3:$AC$29) -> 13 | AH4: =RANK(AC4, $Y$3:$AC$29) -> 16 | AI4: =IF($P4>0, $O4/($P4+AI$2), 0) -> 35297.708 | AJ4: =IF($P4>0, $O4/($P4+AJ$2), 0) -> 33885.8 | AK4: =IF($P4>0, $O4/($P4+AK$2), 0) -> 32582.5 | AL4: =IF($P4>0, $O4/($P4+AL$2), 0) -> 31375.741 | AM4: =IF($P4>0, $O4/($P4+AM$2), 0) -> 30255.179 | AN4: =IF($T4>0, $S4/($T4+AN$2), 0) -> 36031.333 | AO4: =IF($T4>0, $S4/($T4+AO$2), 0) -> 33259.692 | AP4: =IF($T4>0, $S4/($T4+AP$2), 0) -> 30884 | AQ4: =IF($T4>0, $S4/($T4+AQ$2), 0) -> 28825.067 | AR4: =IF($T4>0, $S4/($T4+AR$2), 0) -> 27023.5 | AS4: =RANK(AI4, $AI4:$AR4) -> 2 | AT4: =RANK(AJ4, $AI4:$AR4) -> 3 | AU4: =RANK(AK4, $AI4:$AR4) -> 5 | AV4: =RANK(AL4, $AI4:$AR4) -> 6 | AW4: =RANK(AM4, $AI4:$AR4) -> 8 | AX4: =RANK(AN4, $AI4:$AR4) -> 1 | AY4: =RANK(AO4, $AI4:$AR4) -> 4 | AZ4: =RANK(AP4, $AI4:$AR4) -> 7 | ... BB4: =RANK(AR4, $AI4:$AR4) -> 10 | BE4: פה | BF4: כן | BI4: יש עתיד-המחנה הממלכתי | BJ4: 1 | BK4: =BJ4&BI4 -> 1יש עתיד-המחנה הממלכתי | BL4: =if(BJ4=AS4, $BE4, IF(BJ4=AT4, $BE4, IF(BJ4=AX4, BF4))) -> כן | BO4: 2 | BP4: =if(AT4=BO4, $BE4, $BF4) -> כן
A5: ט | B5: הציונות הדתית | C5: ='תוצאות'!C5 -> 516146 | D5: =E5+F5 -> 14 | E5: =ROUNDDOWN(H5,0) -> 14 | F5: =U3 -> 0 | G5: =IF((C5/(SUM($C$3:C$41))>=$L$2), "כן", "לא") -> כן | H5: =IF(G5="כן", (C5/$K$2), 0) -> 14.252799 | I5: =IF(G5="כן", $K$2*(E5+1)-C5, "") -> 27058.875 | N5: שס | O5: =C7 -> 392644 | P5: =E7 -> 10 | Q5: =COUNTIF(AS5:AW5,"<="&V5) -> 1 | R5: ג | S5: =C8 -> 280125 | T5: =E8 -> 7 | U5: =COUNTIF(AX5:BB5,"<="&V5) -> 0 | V5: =COUNTIF(AD5:AH5,"<="&J$2) -> 1 | W5: =IF(P5>0, IF(T5>0, O5+S5, O5), IF(T5>0, S5, 0)) -> 672769 | X5: =P5+T5 -> 17 | Y5: =IF(X5>0, $W5/($X5+Y$2), 0) -> 37376.056 | Z5: =IF(Y5>0, $W5/($X5+Z$2), 0) -> 35408.895 | AA5: =IF(Z5>0, $W5/($X5+AA$2), 0) -> 33638.45 | AB5: =IF(AA5>0, $W5/($X5+AB$2), 0) -> 32036.619 | AC5: =IF(AB5>0, $W5/($X5+AC$2), 0) -> 30580.409 | AD5: =RANK(Y5, $Y$3:$AC$29) -> 1 | AE5: =RANK(Z5, $Y$3:$AC$29) -> 8 | AF5: =RANK(AA5, $Y$3:$AC$29) -> 14 | AG5: =RANK(AB5, $Y$3:$AC$29) -> 18 | AH5: =RANK(AC5, $Y$3:$AC$29) -> 19 | AI5: =IF($P5>0, $O5/($P5+AI$2), 0) -> 35694.909 | AJ5: =IF($P5>0, $O5/($P5+AJ$2), 0) -> 32720.333 | AK5: =IF($P5>0, $O5/($P5+AK$2), 0) -> 30203.385 | AL5: =IF($P5>0, $O5/($P5+AL$2), 0) -> 28046 | AM5: =IF($P5>0, $O5/($P5+AM$2), 0) -> 26176.267 | AN5: =IF($T5>0, $S5/($T5+AN$2), 0) -> 35015.625 | AO5: =IF($T5>0, $S5/($T5+AO$2), 0) -> 31125 | AP5: =IF($T5>0, $S5/($T5+AP$2), 0) -> 28012.5 | AQ5: =IF($T5>0, $S5/($T5+AQ$2), 0) -> 25465.909 | AR5: =IF($T5>0, $S5/($T5+AR$2), 0) -> 23343.75 | AS5: =RANK(AI5, $AI5:$AR5) -> 1 | AT5: =RANK(AJ5, $AI5:$AR5) -> 3 | AU5: =RANK(AK5, $AI5:$AR5) -> 5 | AV5: =RANK(AL5, $AI5:$AR5) -> 6 | AW5: =RANK(AM5, $AI5:$AR5) -> 8 | AX5: =RANK(AN5, $AI5:$AR5) -> 2 | AY5: =RANK(AO5, $AI5:$AR5) -> 4 | AZ5: =RANK(AP5, $AI5:$AR5) -> 7 | ... BB5: =RANK(AR5, $AI5:$AR5) -> 10 | BE5: שס | BF5: ג | BI5: ש"ס-יהדות התורה | BJ5: 1 | BK5: =BJ5&BI5 -> 1ש"ס-יהדות התורה | BL5: =if(BJ5=AS5, $BE5, IF(BJ5=AT5, $BE5, IF(BJ5=AX5, BF5))) -> שס | BO5: 2 | BP5: =if(AT5=BO5, $BE5, $BF5) -> ג
A6: כן | B6: המחנה הממלכתי | C6: ='תוצאות'!C6 -> 432376 | D6: =E6+F6 -> 12 | E6: =ROUNDDOWN(H6,0) -> 11 | F6: =U4 -> 1 | G6: =IF((C6/(SUM($C$3:C$41))>=$L$2), "כן", "לא") -> כן | H6: =IF(G6="כן", (C6/$K$2), 0) -> 11.939584 | I6: =IF(G6="כן", $K$2*(E6+1)-C6, "") -> 2187.9 | N6: אמת | O6: =C10 -> 175922 | P6: =E10 -> 4 | Q6: =COUNTIF(AS6:AW6,"<="&V6) -> 0 | R6: מרצ | S6: =C11 -> 150696 | T6: =E11 -> 0 | U6: =COUNTIF(AX6:BB6,"<="&V6) -> 0 | V6: =COUNTIF(AD6:AH6,"<="&J$2) -> 0 | W6: =IF(P6>0, IF(T6>0, O6+S6, O6), IF(T6>0, S6, 0)) -> 175922 | X6: =P6+T6 -> 4 | Y6: =IF(X6>0, $W6/($X6+Y$2), 0) -> 35184.4 | Z6: =IF(Y6>0, $W6/($X6+Z$2), 0) -> 29320.333 | AA6: =IF(Z6>0, $W6/($X6+AA$2), 0) -> 25131.714 | AB6: =IF(AA6>0, $W6/($X6+AB$2), 0) -> 21990.25 | AC6: =IF(AB6>0, $W6/($X6+AC$2), 0) -> 19546.889 | AD6: =RANK(Y6, $Y$3:$AC$29) -> 9 | AE6: =RANK(Z6, $Y$3:$AC$29) -> 22 | AF6: =RANK(AA6, $Y$3:$AC$29) -> 26 | AG6: =RANK(AB6, $Y$3:$AC$29) -> 30 | AH6: =RANK(AC6, $Y$3:$AC$29) -> 34 | AI6: =IF($P6>0, $O6/($P6+AI$2), 0) -> 35184.4 | AJ6: =IF($P6>0, $O6/($P6+AJ$2), 0) -> 29320.333 | AK6: =IF($P6>0, $O6/($P6+AK$2), 0) -> 25131.714 | AL6: =IF($P6>0, $O6/($P6+AL$2), 0) -> 21990.25 | AM6: =IF($P6>0, $O6/($P6+AM$2), 0) -> 19546.889 | AN6: =IF($T6>0, $S6/($T6+AN$2), 0) -> 0 | AO6: =IF($T6>0, $S6/($T6+AO$2), 0) -> 0 | AP6: =IF($T6>0, $S6/($T6+AP$2), 0) -> 0 | AQ6: =IF($T6>0, $S6/($T6+AQ$2), 0) -> 0 | AR6: =IF($T6>0, $S6/($T6+AR$2), 0) -> 0 | AS6: =RANK(AI6, $AI6:$AR6) -> 1 | AT6: =RANK(AJ6, $AI6:$AR6) -> 2 | AU6: =RANK(AK6, $AI6:$AR6) -> 3 | AV6: =RANK(AL6, $AI6:$AR6) -> 4 | AW6: =RANK(AM6, $AI6:$AR6) -> 5 | AX6: =RANK(AN6, $AI6:$AR6) -> 6 | AY6: =RANK(AO6, $AI6:$AR6) -> 6 | AZ6: =RANK(AP6, $AI6:$AR6) -> 6 | ... BB6: =RANK(AR6, $AI6:$AR6) -> 6 | BE6: אמת | BF6: מרצ | BI6: העבודה-מרצ | BJ6: 1 | BK6: =BJ6&BI6 -> 1העבודה-מרצ | BL6: =if(BJ6=AS6, $BE6, IF(BJ6=AT6, $BE6, IF(BJ6=AX6, BF6))) -> אמת | BO6: 2 | BP6: =if(AT6=BO6, $BE6, $BF6) -> אמת
A7: שס | B7: ש"ס | C7: ='תוצאות'!C7 -> 392644 | D7: =E7+F7 -> 11 | E7: =ROUNDDOWN(H7,0) -> 10 | F7: =Q5 -> 1 | G7: =IF((C7/(SUM($C$3:C$41))>=$L$2), "כן", "לא") -> כן | H7: =IF(G7="כן", (C7/$K$2), 0) -> 10.842428 | I7: =IF(G7="כן", $K$2*(E7+1)-C7, "") -> 5706.2417 | N7: ל | O7: =C9 -> 213655 | P7: =E9 -> 5 | Q7: =COUNTIF(AS7:AW7,"<="&V7) -> 1 | U7: =COUNTIF(AX7:BB7,"<="&V7) -> 0 | V7: =COUNTIF(AD7:AH7,"<="&J$2) -> 1 | W7: =IF(P7>0, IF(T7>0, O7+S7, O7), IF(T7>0, S7, 0)) -> 213655 | X7: =P7+T7 -> 5 | Y7: =IF(X7>0, $W7/($X7+Y$2), 0) -> 35609.167 | Z7: =IF(Y7>0, $W7/($X7+Z$2), 0) -> 30522.143 | AA7: =IF(Z7>0, $W7/($X7+AA$2), 0) -> 26706.875 | AB7: =IF(AA7>0, $W7/($X7+AB$2), 0) -> 23739.444 | AC7: =IF(AB7>0, $W7/($X7+AC$2), 0) -> 21365.5 | AD7: =RANK(Y7, $Y$3:$AC$29) -> 5 | AE7: =RANK(Z7, $Y$3:$AC$29) -> 20 | AF7: =RANK(AA7, $Y$3:$AC$29) -> 24 | AG7: =RANK(AB7, $Y$3:$AC$29) -> 28 | AH7: =RANK(AC7, $Y$3:$AC$29) -> 32 | AI7: =IF($P7>0, $O7/($P7+AI$2), 0) -> 35609.167 | AJ7: =IF($P7>0, $O7/($P7+AJ$2), 0) -> 30522.143 | AK7: =IF($P7>0, $O7/($P7+AK$2), 0) -> 26706.875 | AL7: =IF($P7>0, $O7/($P7+AL$2), 0) -> 23739.444 | AM7: =IF($P7>0, $O7/($P7+AM$2), 0) -> 21365.5 | AN7: =IF($T7>0, $S7/($T7+AN$2), 0) -> 0 | AO7: =IF($T7>0, $S7/($T7+AO$2), 0) -> 0 | AP7: =IF($T7>0, $S7/($T7+AP$2), 0) -> 0 | AQ7: =IF($T7>0, $S7/($T7+AQ$2), 0) -> 0 | AR7: =IF($T7>0, $S7/($T7+AR$2), 0) -> 0 | AS7: =RANK(AI7, $AI7:$AR7) -> 1 | AT7: =RANK(AJ7, $AI7:$AR7) -> 2 | AU7: =RANK(AK7, $AI7:$AR7) -> 3 | AV7: =RANK(AL7, $AI7:$AR7) -> 4 | AW7: =RANK(AM7, $AI7:$AR7) -> 5 | AX7: =RANK(AN7, $AI7:$AR7) -> 6 | AY7: =RANK(AO7, $AI7:$AR7) -> 6 | AZ7: =RANK(AP7, $AI7:$AR7) -> 6 | ... BB7: =RANK(AR7, $AI7:$AR7) -> 6 | BE7: ל | BI7: ישראל ביתנו | BJ7: 1 | BK7: =BJ7&BI7 -> 1ישראל ביתנו | BL7: =if(BJ7=AS7, $BE7, IF(BJ7=AT7, $BE7, IF(BJ7=AX7, BF7))) -> ל | BO7: 2 | BP7: =if(AT7=BO7, $BE7, $BF7) -> ל
A8: ג | B8: יהדות התורה | C8: ='תוצאות'!C8 -> 280125 | D8: =E8+F8 -> 7 | E8: =ROUNDDOWN(H8,0) -> 7 | F8: =U5 -> 0 | G8: =IF((C8/(SUM($C$3:C$41))>=$L$2), "כן", "לא") -> כן | H8: =IF(G8="כן", (C8/$K$2), 0) -> 7.7353411 | I8: =IF(G8="כן", $K$2*(E8+1)-C8, "") -> 9584.2667 | N8: ום | O8: =C12 -> 178661 | P8: =E12 -> 4 | Q8: =COUNTIF(AS8:AW8,"<="&V8) -> 1 | U8: =COUNTIF(AX8:BB8,"<="&V8) -> 0 | V8: =COUNTIF(AD8:AH8,"<="&J$2) -> 1 | W8: =IF(P8>0, IF(T8>0, O8+S8, O8), IF(T8>0, S8, 0)) -> 178661 | X8: =P8+T8 -> 4 | Y8: =IF(X8>0, $W8/($X8+Y$2), 0) -> 35732.2 | Z8: =IF(Y8>0, $W8/($X8+Z$2), 0) -> 29776.833 | AA8: =IF(Z8>0, $W8/($X8+AA$2), 0) -> 25523 | AB8: =IF(AA8>0, $W8/($X8+AB$2), 0) -> 22332.625 | AC8: =IF(AB8>0, $W8/($X8+AC$2), 0) -> 19851.222 | AD8: =RANK(Y8, $Y$3:$AC$29) -> 4 | AE8: =RANK(Z8, $Y$3:$AC$29) -> 21 | AF8: =RANK(AA8, $Y$3:$AC$29) -> 25 | AG8: =RANK(AB8, $Y$3:$AC$29) -> 29 | AH8: =RANK(AC8, $Y$3:$AC$29) -> 33 | AI8: =IF($P8>0, $O8/($P8+AI$2), 0) -> 35732.2 | AJ8: =IF($P8>0, $O8/($P8+AJ$2), 0) -> 29776.833 | AK8: =IF($P8>0, $O8/($P8+AK$2), 0) -> 25523 | AL8: =IF($P8>0, $O8/($P8+AL$2), 0) -> 22332.625 | AM8: =IF($P8>0, $O8/($P8+AM$2), 0) -> 19851.222 | AN8: =IF($T8>0, $S8/($T8+AN$2), 0) -> 0 | AO8: =IF($T8>0, $S8/($T8+AO$2), 0) -> 0 | AP8: =IF($T8>0, $S8/($T8+AP$2), 0) -> 0 | AQ8: =IF($T8>0, $S8/($T8+AQ$2), 0) -> 0 | AR8: =IF($T8>0, $S8/($T8+AR$2), 0) -> 0 | AS8: =RANK(AI8, $AI8:$AR8) -> 1 | AT8: =RANK(AJ8, $AI8:$AR8) -> 2 | AU8: =RANK(AK8, $AI8:$AR8) -> 3 | AV8: =RANK(AL8, $AI8:$AR8) -> 4 | AW8: =RANK(AM8, $AI8:$AR8) -> 5 | AX8: =RANK(AN8, $AI8:$AR8) -> 6 | AY8: =RANK(AO8, $AI8:$AR8) -> 6 | AZ8: =RANK(AP8, $AI8:$AR8) -> 6 | ... BB8: =RANK(AR8, $AI8:$AR8) -> 6 | BE8: ום | BI8: חד"ש-תע"ל | BJ8: 1 | BK8: =BJ8&BI8 -> 1חד"ש-תע"ל | BL8: =if(BJ8=AS8, $BE8, IF(BJ8=AT8, $BE8, IF(BJ8=AX8, BF8))) -> ום | BO8: 2 | BP8: =if(AT8=BO8, $BE8, $BF8) -> ום
A9: ל | B9: ישראל ביתנו | C9: ='תוצאות'!C9 -> 213655 | D9: =E9+F9 -> 6 | E9: =ROUNDDOWN(H9,0) -> 5 | F9: =Q7 -> 1 | G9: =IF((C9/(SUM($C$3:C$41))>=$L$2), "כן", "לא") -> כן | H9: =IF(G9="כן", (C9/$K$2), 0) -> 5.8998458 | I9: =IF(G9="כן", $K$2*(E9+1)-C9, "") -> 3626.95 | N9: עם | O9: =C13 -> 193916 | P9: =E13 -> 5 | Q9: =COUNTIF(AS9:AW9,"<="&V9) -> 0 | U9: =COUNTIF(AX9:BB9,"<="&V9) -> 0 | V9: =COUNTIF(AD9:AH9,"<="&J$2) -> 0 | W9: =IF(P9>0, IF(T9>0, O9+S9, O9), IF(T9>0, S9, 0)) -> 193916 | X9: =P9+T9 -> 5 | Y9: =IF(X9>0, $W9/($X9+Y$2), 0) -> 32319.333 | Z9: =IF(Y9>0, $W9/($X9+Z$2), 0) -> 27702.286 | AA9: =IF(Z9>0, $W9/($X9+AA$2), 0) -> 24239.5 | AB9: =IF(AA9>0, $W9/($X9+AB$2), 0) -> 21546.222 | AC9: =IF(AB9>0, $W9/($X9+AC$2), 0) -> 19391.6 | AD9: =RANK(Y9, $Y$3:$AC$29) -> 17 | AE9: =RANK(Z9, $Y$3:$AC$29) -> 23 | AF9: =RANK(AA9, $Y$3:$AC$29) -> 27 | AG9: =RANK(AB9, $Y$3:$AC$29) -> 31 | AH9: =RANK(AC9, $Y$3:$AC$29) -> 35 | AI9: =IF($P9>0, $O9/($P9+AI$2), 0) -> 32319.333 | AJ9: =IF($P9>0, $O9/($P9+AJ$2), 0) -> 27702.286 | AK9: =IF($P9>0, $O9/($P9+AK$2), 0) -> 24239.5 | AL9: =IF($P9>0, $O9/($P9+AL$2), 0) -> 21546.222 | AM9: =IF($P9>0, $O9/($P9+AM$2), 0) -> 19391.6 | AN9: =IF($T9>0, $S9/($T9+AN$2), 0) -> 0 | AO9: =IF($T9>0, $S9/($T9+AO$2), 0) -> 0 | AP9: =IF($T9>0, $S9/($T9+AP$2), 0) -> 0 | AQ9: =IF($T9>0, $S9/($T9+AQ$2), 0) -> 0 | AR9: =IF($T9>0, $S9/($T9+AR$2), 0) -> 0 | AS9: =RANK(AI9, $AI9:$AR9) -> 1 | AT9: =RANK(AJ9, $AI9:$AR9) -> 2 | AU9: =RANK(AK9, $AI9:$AR9) -> 3 | AV9: =RANK(AL9, $AI9:$AR9) -> 4 | AW9: =RANK(AM9, $AI9:$AR9) -> 5 | AX9: =RANK(AN9, $AI9:$AR9) -> 6 | AY9: =RANK(AO9, $AI9:$AR9) -> 6 | AZ9: =RANK(AP9, $AI9:$AR9) -> 6 | ... BB9: =RANK(AR9, $AI9:$AR9) -> 6 | BE9: עם | BI9: רע"ם | BJ9: 1 | BK9: =BJ9&BI9 -> 1רע"ם | BL9: =if(BJ9=AS9, $BE9, IF(BJ9=AT9, $BE9, IF(BJ9=AX9, BF9))) -> עם | BO9: 2 | BP9: =if(AT9=BO9, $BE9, $BF9) -> עם
A10: אמת | B10: העבודה | C10: ='תוצאות'!C10 -> 175922 | D10: =E10+F10 -> 4 | E10: =ROUNDDOWN(H10,0) -> 4 | F10: =Q6 -> 0 | G10: =IF((C10/(SUM($C$3:C$41))>=$L$2), "כן", "לא") -> כן | H10: =IF(G10="כן", (C10/$K$2), 0) -> 4.8578909 | I10: =IF(G10="כן", $K$2*(E10+1)-C10, "") -> 5146.2917 | N10: ד | O10: =C14 -> 138093 | P10: =E14 -> 0 | Q10: =COUNTIF(AS10:AW10,"<="&V10) -> 0 | U10: =COUNTIF(AX10:BB10,"<="&V10) -> 0 | V10: =COUNTIF(AD10:AH10,"<="&J$2) -> 0 | W10: =IF(P10>0, IF(T10>0, O10+S10, O10), IF(T10>0, S10, 0)) -> 0 | X10: =P10+T10 -> 0 | Y10: =IF(X10>0, $W10/($X10+Y$2), 0) -> 0 | Z10: =IF(Y10>0, $W10/($X10+Z$2), 0) -> 0 | AA10: =IF(Z10>0, $W10/($X10+AA$2), 0) -> 0 | AB10: =IF(AA10>0, $W10/($X10+AB$2), 0) -> 0 | AC10: =IF(AB10>0, $W10/($X10+AC$2), 0) -> 0 | AD10: =RANK(Y10, $Y$3:$AC$29) -> 36 | AE10: =RANK(Z10, $Y$3:$AC$29) -> 36 | AF10: =RANK(AA10, $Y$3:$AC$29) -> 36 | AG10: =RANK(AB10, $Y$3:$AC$29) -> 36 | AH10: =RANK(AC10, $Y$3:$AC$29) -> 36 | AI10: =IF($P10>0, $O10/($P10+AI$2), 0) -> 0 | AJ10: =IF($P10>0, $O10/($P10+AJ$2), 0) -> 0 | AK10: =IF($P10>0, $O10/($P10+AK$2), 0) -> 0 | AL10: =IF($P10>0, $O10/($P10+AL$2), 0) -> 0 | AM10: =IF($P10>0, $O10/($P10+AM$2), 0) -> 0 | AN10: =IF($T10>0, $S10/($T10+AN$2), 0) -> 0 | AO10: =IF($T10>0, $S10/($T10+AO$2), 0) -> 0 | AP10: =IF($T10>0, $S10/($T10+AP$2), 0) -> 0 | AQ10: =IF($T10>0, $S10/($T10+AQ$2), 0) -> 0 | AR10: =IF($T10>0, $S10/($T10+AR$2), 0) -> 0 | AS10: =RANK(AI10, $AI10:$AR10) -> 1 | AT10: =RANK(AJ10, $AI10:$AR10) -> 1 | AU10: =RANK(AK10, $AI10:$AR10) -> 1 | AV10: =RANK(AL10, $AI10:$AR10) -> 1 | AW10: =RANK(AM10, $AI10:$AR10) -> 1 | AX10: =RANK(AN10, $AI10:$AR10) -> 1 | AY10: =RANK(AO10, $AI10:$AR10) -> 1 | AZ10: =RANK(AP10, $AI10:$AR10) -> 1 | ... BB10: =RANK(AR10, $AI10:$AR10) -> 1 | BE10: ד | BI10: בל"ד | BJ10: 1 | BK10: =BJ10&BI10 -> 1בל"ד | BL10: =if(BJ10=AS10, $BE10, IF(BJ10=AT10, $BE10, IF(BJ10=AX10, BF10))) -> ד | BO10: 2 | BP10: =if(AT10=BO10, $BE10, $BF10)
A11: מרצ | B11: מרצ | C11: ='תוצאות'!C11 -> 150696 | D11: =E11+F11 -> 0 | E11: =ROUNDDOWN(H11,0) -> 0 | F11: =U6 -> 0 | G11: =IF((C11/(SUM($C$3:C$41))>=$L$2), "כן", "לא") -> לא | H11: =IF(G11="כן", (C11/$K$2), 0) -> 0 | I11: =IF(G11="כן", $K$2*(E11+1)-C11, "") | N11: ב | O11: =C15 -> 56793 | P11: =E15 -> 0 | Q11: =COUNTIF(AS11:AW11,"<="&V11) -> 0 | U11: =COUNTIF(AX11:BB11,"<="&V11) -> 0 | V11: =COUNTIF(AD11:AH11,"<="&J$2) -> 0 | W11: =IF(P11>0, IF(T11>0, O11+S11, O11), IF(T11>0, S11, 0)) -> 0 | X11: =P11+T11 -> 0 | Y11: =IF(X11>0, $W11/($X11+Y$2), 0) -> 0 | Z11: =IF(Y11>0, $W11/($X11+Z$2), 0) -> 0 | AA11: =IF(Z11>0, $W11/($X11+AA$2), 0) -> 0 | AB11: =IF(AA11>0, $W11/($X11+AB$2), 0) -> 0 | AC11: =IF(AB11>0, $W11/($X11+AC$2), 0) -> 0 | AD11: =RANK(Y11, $Y$3:$AC$29) -> 36 | AE11: =RANK(Z11, $Y$3:$AC$29) -> 36 | AF11: =RANK(AA11, $Y$3:$AC$29) -> 36 | AG11: =RANK(AB11, $Y$3:$AC$29) -> 36 | AH11: =RANK(AC11, $Y$3:$AC$29) -> 36 | AI11: =IF($P11>0, $O11/($P11+AI$2), 0) -> 0 | AJ11: =IF($P11>0, $O11/($P11+AJ$2), 0) -> 0 | AK11: =IF($P11>0, $O11/($P11+AK$2), 0) -> 0 | AL11: =IF($P11>0, $O11/($P11+AL$2), 0) -> 0 | AM11: =IF($P11>0, $O11/($P11+AM$2), 0) -> 0 | AN11: =IF($T11>0, $S11/($T11+AN$2), 0) -> 0 | AO11: =IF($T11>0, $S11/($T11+AO$2), 0) -> 0 | AP11: =IF($T11>0, $S11/($T11+AP$2), 0) -> 0 | AQ11: =IF($T11>0, $S11/($T11+AQ$2), 0) -> 0 | AR11: =IF($T11>0, $S11/($T11+AR$2), 0) -> 0 | AS11: =RANK(AI11, $AI11:$AR11) -> 1 | AT11: =RANK(AJ11, $AI11:$AR11) -> 1 | AU11: =RANK(AK11, $AI11:$AR11) -> 1 | AV11: =RANK(AL11, $AI11:$AR11) -> 1 | AW11: =RANK(AM11, $AI11:$AR11) -> 1 | AX11: =RANK(AN11, $AI11:$AR11) -> 1 | AY11: =RANK(AO11, $AI11:$AR11) -> 1 | AZ11: =RANK(AP11, $AI11:$AR11) -> 1 | ... BB11: =RANK(AR11, $AI11:$AR11) -> 1 | BE11: ב | BI11: הבית היהודי | BJ11: 1 | BK11: =BJ11&BI11 -> 1הבית היהודי | BL11: =if(BJ11=AS11, $BE11, IF(BJ11=AT11, $BE11, IF(BJ11=AX11, BF11))) -> ב | BO11: 2 | BP11: =if(AT11=BO11, $BE11, $BF11)
A12: ום | B12: חד"ש-תע"ל | C12: ='תוצאות'!C12 -> 178661 | D12: =E12+F12 -> 5 | E12: =ROUNDDOWN(H12,0) -> 4 | F12: =Q8 -> 1 | G12: =IF((C12/(SUM($C$3:C$41))>=$L$2), "כן", "לא") -> כן | H12: =IF(G12="כן", (C12/$K$2), 0) -> 4.9335253 | I12: =IF(G12="כן", $K$2*(E12+1)-C12, "") -> 2407.2917 | N12: יז | O12: =C16 -> 13911 | P12: =E16 -> 0 | Q12: =COUNTIF(AS12:AW12,"<="&V12) -> 0 | U12: =COUNTIF(AX12:BB12,"<="&V12) -> 0 | V12: =COUNTIF(AD12:AH12,"<="&J$2) -> 0 | W12: =IF(P12>0, IF(T12>0, O12+S12, O12), IF(T12>0, S12, 0)) -> 0 | X12: =P12+T13 -> 0 | Y12: =IF(X12>0, $W12/($X12+Y$2), 0) -> 0 | Z12: =IF(Y12>0, $W12/($X12+Z$2), 0) -> 0 | AA12: =IF(Z12>0, $W12/($X12+AA$2), 0) -> 0 | AB12: =IF(AA12>0, $W12/($X12+AB$2), 0) -> 0 | AC12: =IF(AB12>0, $W12/($X12+AC$2), 0) -> 0 | AD12: =RANK(Y12, $Y$3:$AC$29) -> 36 | AE12: =RANK(Z12, $Y$3:$AC$29) -> 36 | AF12: =RANK(AA12, $Y$3:$AC$29) -> 36 | AG12: =RANK(AB12, $Y$3:$AC$29) -> 36 | AH12: =RANK(AC12, $Y$3:$AC$29) -> 36 | AI12: =IF($P12>0, $O12/($P12+AI$2), 0) -> 0 | AJ12: =IF($P12>0, $O12/($P12+AJ$2), 0) -> 0 | AK12: =IF($P12>0, $O12/($P12+AK$2), 0) -> 0 | AL12: =IF($P12>0, $O12/($P12+AL$2), 0) -> 0 | AM12: =IF($P12>0, $O12/($P12+AM$2), 0) -> 0 | AN12: =IF($T13>0, $S13/($T13+AN$2), 0) -> 0 | AO12: =IF($T13>0, $S13/($T13+AO$2), 0) -> 0 | AP12: =IF($T13>0, $S13/($T13+AP$2), 0) -> 0 | AQ12: =IF($T13>0, $S13/($T13+AQ$2), 0) -> 0 | AR12: =IF($T13>0, $S13/($T13+AR$2), 0) -> 0 | AS12: =RANK(AI12, $AI12:$AR12) -> 1 | AT12: =RANK(AJ12, $AI12:$AR12) -> 1 | AU12: =RANK(AK12, $AI12:$AR12) -> 1 | AV12: =RANK(AL12, $AI12:$AR12) -> 1 | AW12: =RANK(AM12, $AI12:$AR12) -> 1 | AX12: =RANK(AN12, $AI12:$AR12) -> 1 | AY12: =RANK(AO12, $AI12:$AR12) -> 1 | AZ12: =RANK(AP12, $AI12:$AR12) -> 1 | ... BB12: =RANK(AR12, $AI12:$AR12) -> 1 | BI12: ליכוד-ציונות דתית | BJ12: 2 | BK12: =BJ12&BI12 -> 2ליכוד-ציונות דתית | BL12: =if(BJ12=AS3, $BE3, IF(BJ12=AT3, $BE3, IF(BJ12=AX3, BF3, ""))) -> מחל
A13: עם | B13: רע"ם | C13: ='תוצאות'!C13 -> 193916 | D13: =E13+F13 -> 5 | E13: =ROUNDDOWN(H13,0) -> 5 | F13: =Q9 -> 0 | G13: =IF((C13/(SUM($C$3:C$41))>=$L$2), "כן", "לא") -> כן | H13: =IF(G13="כן", (C13/$K$2), 0) -> 5.3547752 | I13: =IF(G13="כן", $K$2*(E13+1)-C13, "") -> 23365.95 | N13: י | O13: =C17 -> 1156 | P13: =E17 -> 0 | Q13: =COUNTIF(AS13:AW13,"<="&V13) -> 0 | U13: =COUNTIF(AX13:BB13,"<="&V13) -> 0 | V13: =COUNTIF(AD13:AH13,"<="&J$2) -> 0 | W13: =IF(P13>0, IF(T13>0, O13+S13, O13), IF(T13>0, S13, 0)) -> 0 | X13: =P13+T14 -> 0 | Y13: =IF(X13>0, $W13/($X13+Y$2), 0) -> 0 | Z13: =IF(Y13>0, $W13/($X13+Z$2), 0) -> 0 | AA13: =IF(Z13>0, $W13/($X13+AA$2), 0) -> 0 | AB13: =IF(AA13>0, $W13/($X13+AB$2), 0) -> 0 | AC13: =IF(AB13>0, $W13/($X13+AC$2), 0) -> 0 | AD13: =RANK(Y13, $Y$3:$AC$29) -> 36 | AE13: =RANK(Z13, $Y$3:$AC$29) -> 36 | AF13: =RANK(AA13, $Y$3:$AC$29) -> 36 | AG13: =RANK(AB13, $Y$3:$AC$29) -> 36 | AH13: =RANK(AC13, $Y$3:$AC$29) -> 36 | AI13: =IF($P13>0, $O13/($P13+AI$2), 0) -> 0 | AJ13: =IF($P13>0, $O13/($P13+AJ$2), 0) -> 0 | AK13: =IF($P13>0, $O13/($P13+AK$2), 0) -> 0 | AL13: =IF($P13>0, $O13/($P13+AL$2), 0) -> 0 | AM13: =IF($P13>0, $O13/($P13+AM$2), 0) -> 0 | AN13: =IF($T14>0, $S14/($T14+AN$2), 0) -> 0 | AO13: =IF($T14>0, $S14/($T14+AO$2), 0) -> 0 | AP13: =IF($T14>0, $S14/($T14+AP$2), 0) -> 0 | AQ13: =IF($T14>0, $S14/($T14+AQ$2), 0) -> 0 | AR13: =IF($T14>0, $S14/($T14+AR$2), 0) -> 0 | AS13: =RANK(AI13, $AI13:$AR13) -> 1 | AT13: =RANK(AJ13, $AI13:$AR13) -> 1 | AU13: =RANK(AK13, $AI13:$AR13) -> 1 | AV13: =RANK(AL13, $AI13:$AR13) -> 1 | AW13: =RANK(AM13, $AI13:$AR13) -> 1 | AX13: =RANK(AN13, $AI13:$AR13) -> 1 | AY13: =RANK(AO13, $AI13:$AR13) -> 1 | AZ13: =RANK(AP13, $AI13:$AR13) -> 1 | ... BB13: =RANK(AR13, $AI13:$AR13) -> 1 | BI13: יש עתיד-המחנה הממלכתי | BJ13: 2 | BK13: =BJ13&BI13 -> 2יש עתיד-המחנה הממלכתי | BL13: =if(BJ13=AS4, $BE4, IF(BJ13=AT4, $BE4, IF(BJ13=AX4, BF4, ""))) -> פה
A14: ד | B14: בל"ד | C14: ='תוצאות'!C14 -> 138093 | D14: =E14+F14 -> 0 | E14: =ROUNDDOWN(H14,0) -> 0 | F14: =Q10 -> 0 | G14: =IF((C14/(SUM($C$3:C$41))>=$L$2), "כן", "לא") -> לא | H14: =IF(G14="כן", (C14/$K$2), 0) -> 0 | I14: =IF(G14="כן", $K$2*(E14+1)-C14, "") | N14: צ | O14: =C18 -> 8794 | P14: =E18 -> 0 | Q14: =COUNTIF(AS14:AW14,"<="&V14) -> 0 | U14: =COUNTIF(AX14:BB14,"<="&V14) -> 0 | V14: =COUNTIF(AD14:AH14,"<="&J$2) -> 0 | W14: =IF(P14>0, IF(T14>0, O14+S14, O14), IF(T14>0, S14, 0)) -> 0 | X14: =P14+T15 -> 0 | Y14: =IF(X14>0, $W14/($X14+Y$2), 0) -> 0 | Z14: =IF(Y14>0, $W14/($X14+Z$2), 0) -> 0 | AA14: =IF(Z14>0, $W14/($X14+AA$2), 0) -> 0 | AB14: =IF(AA14>0, $W14/($X14+AB$2), 0) -> 0 | AC14: =IF(AB14>0, $W14/($X14+AC$2), 0) -> 0 | AD14: =RANK(Y14, $Y$3:$AC$29) -> 36 | AE14: =RANK(Z14, $Y$3:$AC$29) -> 36 | AF14: =RANK(AA14, $Y$3:$AC$29) -> 36 | AG14: =RANK(AB14, $Y$3:$AC$29) -> 36 | AH14: =RANK(AC14, $Y$3:$AC$29) -> 36 | AI14: =IF($P14>0, $O14/($P14+AI$2), 0) -> 0 | AJ14: =IF($P14>0, $O14/($P14+AJ$2), 0) -> 0 | AK14: =IF($P14>0, $O14/($P14+AK$2), 0) -> 0 | AL14: =IF($P14>0, $O14/($P14+AL$2), 0) -> 0 | AM14: =IF($P14>0, $O14/($P14+AM$2), 0) -> 0 | AN14: =IF($T15>0, $S15/($T15+AN$2), 0) -> 0 | AO14: =IF($T15>0, $S15/($T15+AO$2), 0) -> 0 | AP14: =IF($T15>0, $S15/($T15+AP$2), 0) -> 0 | AQ14: =IF($T15>0, $S15/($T15+AQ$2), 0) -> 0 | AR14: =IF($T15>0, $S15/($T15+AR$2), 0) -> 0 | AS14: =RANK(AI14, $AI14:$AR14) -> 1 | AT14: =RANK(AJ14, $AI14:$AR14) -> 1 | AU14: =RANK(AK14, $AI14:$AR14) -> 1 | AV14: =RANK(AL14, $AI14:$AR14) -> 1 | AW14: =RANK(AM14, $AI14:$AR14) -> 1 | AX14: =RANK(AN14, $AI14:$AR14) -> 1 | AY14: =RANK(AO14, $AI14:$AR14) -> 1 | AZ14: =RANK(AP14, $AI14:$AR14) -> 1 | ... BB14: =RANK(AR14, $AI14:$AR14) -> 1 | BI14: ש"ס-יהדות התורה | BJ14: 2 | BK14: =BJ14&BI14 -> 2ש"ס-יהדות התורה | BL14: =if(BJ14=AS5, $BE5, IF(BJ14=AT5, $BE5, IF(BJ14=AX5, BF5, ""))) -> ג
A15: ב | B15: הבית היהודי | C15: ='תוצאות'!C15 -> 56793 | D15: =E15+F15 -> 0 | E15: =ROUNDDOWN(H15,0) -> 0 | F15: =Q11 -> 0 | G15: =IF((C15/(SUM($C$3:C$41))>=$L$2), "כן", "לא") -> לא | H15: =IF(G15="כן", (C15/$K$2), 0) -> 0 | I15: =IF(G15="כן", $K$2*(E15+1)-C15, "") | N15: אצ | O15: =C19 -> 15817 | P15: =E19 -> 0 | Q15: =COUNTIF(AS15:AW15,"<="&V15) -> 0 | U15: =COUNTIF(AX15:BB15,"<="&V15) -> 0 | V15: =COUNTIF(AD15:AH15,"<="&J$2) -> 0 | W15: =IF(P15>0, IF(T15>0, O15+S15, O15), IF(T15>0, S15, 0)) -> 0 | X15: =P15+T16 -> 0 | Y15: =IF(X15>0, $W15/($X15+Y$2), 0) -> 0 | Z15: =IF(Y15>0, $W15/($X15+Z$2), 0) -> 0 | AA15: =IF(Z15>0, $W15/($X15+AA$2), 0) -> 0 | AB15: =IF(AA15>0, $W15/($X15+AB$2), 0) -> 0 | AC15: =IF(AB15>0, $W15/($X15+AC$2), 0) -> 0 | AD15: =RANK(Y15, $Y$3:$AC$29) -> 36 | AE15: =RANK(Z15, $Y$3:$AC$29) -> 36 | AF15: =RANK(AA15, $Y$3:$AC$29) -> 36 | AG15: =RANK(AB15, $Y$3:$AC$29) -> 36 | AH15: =RANK(AC15, $Y$3:$AC$29) -> 36 | AI15: =IF($P15>0, $O15/($P15+AI$2), 0) -> 0 | AJ15: =IF($P15>0, $O15/($P15+AJ$2), 0) -> 0 | AK15: =IF($P15>0, $O15/($P15+AK$2), 0) -> 0 | AL15: =IF($P15>0, $O15/($P15+AL$2), 0) -> 0 | AM15: =IF($P15>0, $O15/($P15+AM$2), 0) -> 0 | AN15: =IF($T16>0, $S16/($T16+AN$2), 0) -> 0 | AO15: =IF($T16>0, $S16/($T16+AO$2), 0) -> 0 | AP15: =IF($T16>0, $S16/($T16+AP$2), 0) -> 0 | AQ15: =IF($T16>0, $S16/($T16+AQ$2), 0) -> 0 | AR15: =IF($T16>0, $S16/($T16+AR$2), 0) -> 0 | AS15: =RANK(AI15, $AI15:$AR15) -> 1 | AT15: =RANK(AJ15, $AI15:$AR15) -> 1 | AU15: =RANK(AK15, $AI15:$AR15) -> 1 | AV15: =RANK(AL15, $AI15:$AR15) -> 1 | AW15: =RANK(AM15, $AI15:$AR15) -> 1 | AX15: =RANK(AN15, $AI15:$AR15) -> 1 | AY15: =RANK(AO15, $AI15:$AR15) -> 1 | AZ15: =RANK(AP15, $AI15:$AR15) -> 1 | ... BB15: =RANK(AR15, $AI15:$AR15) -> 1 | BI15: העבודה-מרצ | BJ15: 2 | BK15: =BJ15&BI15 -> 2העבודה-מרצ | BL15: =if(BJ15=AS6, $BE6, IF(BJ15=AT6, $BE6, IF(BJ15=AX6, BF6, ""))) -> אמת
A16: יז | B16: הכלכלית החדשה | C16: ='תוצאות'!C16 -> 13911 | D16: =E16+F16 -> 0 | E16: =ROUNDDOWN(H16,0) -> 0 | F16: =Q12 -> 0 | G16: =IF((C16/(SUM($C$3:C$41))>=$L$2), "כן", "לא") -> לא | H16: =IF(G16="כן", (C16/$K$2), 0) -> 0 | I16: =IF(G16="כן", $K$2*(E16+1)-C16, "") | N16: ז | O16: =C20 -> 530 | P16: =E20 -> 0 | Q16: =COUNTIF(AS16:AW16,"<="&V16) -> 0 | U16: =COUNTIF(AX16:BB16,"<="&V16) -> 0 | V16: =COUNTIF(AD16:AH16,"<="&J$2) -> 0 | W16: =IF(P16>0, IF(T16>0, O16+S16, O16), IF(T16>0, S16, 0)) -> 0 | X16: =P16+T17 -> 0 | Y16: =IF(X16>0, $W16/($X16+Y$2), 0) -> 0 | Z16: =IF(Y16>0, $W16/($X16+Z$2), 0) -> 0 | AA16: =IF(Z16>0, $W16/($X16+AA$2), 0) -> 0 | AB16: =IF(AA16>0, $W16/($X16+AB$2), 0) -> 0 | AC16: =IF(AB16>0, $W16/($X16+AC$2), 0) -> 0 | AD16: =RANK(Y16, $Y$3:$AC$29) -> 36 | AE16: =RANK(Z16, $Y$3:$AC$29) -> 36 | AF16: =RANK(AA16, $Y$3:$AC$29) -> 36 | AG16: =RANK(AB16, $Y$3:$AC$29) -> 36 | AH16: =RANK(AC16, $Y$3:$AC$29) -> 36 | AI16: =IF($P16>0, $O16/($P16+AI$2), 0) -> 0 | AJ16: =IF($P16>0, $O16/($P16+AJ$2), 0) -> 0 | AK16: =IF($P16>0, $O16/($P16+AK$2), 0) -> 0 | AL16: =IF($P16>0, $O16/($P16+AL$2), 0) -> 0 | AM16: =IF($P16>0, $O16/($P16+AM$2), 0) -> 0 | AN16: =IF($T17>0, $S17/($T17+AN$2), 0) -> 0 | AO16: =IF($T17>0, $S17/($T17+AO$2), 0) -> 0 | AP16: =IF($T17>0, $S17/($T17+AP$2), 0) -> 0 | AQ16: =IF($T17>0, $S17/($T17+AQ$2), 0) -> 0 | AR16: =IF($T17>0, $S17/($T17+AR$2), 0) -> 0 | AS16: =RANK(AI16, $AI16:$AR16) -> 1 | AT16: =RANK(AJ16, $AI16:$AR16) -> 1 | AU16: =RANK(AK16, $AI16:$AR16) -> 1 | AV16: =RANK(AL16, $AI16:$AR16) -> 1 | AW16: =RANK(AM16, $AI16:$AR16) -> 1 | AX16: =RANK(AN16, $AI16:$AR16) -> 1 | AY16: =RANK(AO16, $AI16:$AR16) -> 1 | AZ16: =RANK(AP16, $AI16:$AR16) -> 1 | ... BB16: =RANK(AR16, $AI16:$AR16) -> 1 | BI16: ישראל ביתנו | BJ16: 2 | BK16: =BJ16&BI16 -> 2ישראל ביתנו | BL16: =if(BJ16=AS7, $BE7, IF(BJ16=AT7, $BE7, IF(BJ16=AX7, BF7, ""))) -> ל
A17: י | B17: ישראל חופשית | C17: ='תוצאות'!C17 -> 1156 | D17: =E17+F17 -> 0 | E17: =ROUNDDOWN(H17,0) -> 0 | F17: =Q13 -> 0 | G17: =IF((C17/(SUM($C$3:C$41))>=$L$2), "כן", "לא") -> לא | H17: =IF(G17="כן", (C17/$K$2), 0) -> 0 | I17: =IF(G17="כן", $K$2*(E17+1)-C17, "") | N17: זך | O17: =C21 -> 205 | P17: =E21 -> 0 | Q17: =COUNTIF(AS17:AW17,"<="&V17) -> 0 | U17: =COUNTIF(AX17:BB17,"<="&V17) -> 0 | V17: =COUNTIF(AD17:AH17,"<="&J$2) -> 0 | W17: =IF(P17>0, IF(T17>0, O17+S17, O17), IF(T17>0, S17, 0)) -> 0 | X17: =P17+T18 -> 0 | Y17: =IF(X17>0, $W17/($X17+Y$2), 0) -> 0 | Z17: =IF(Y17>0, $W17/($X17+Z$2), 0) -> 0 | AA17: =IF(Z17>0, $W17/($X17+AA$2), 0) -> 0 | AB17: =IF(AA17>0, $W17/($X17+AB$2), 0) -> 0 | AC17: =IF(AB17>0, $W17/($X17+AC$2), 0) -> 0 | AD17: =RANK(Y17, $Y$3:$AC$29) -> 36 | AE17: =RANK(Z17, $Y$3:$AC$29) -> 36 | AF17: =RANK(AA17, $Y$3:$AC$29) -> 36 | AG17: =RANK(AB17, $Y$3:$AC$29) -> 36 | AH17: =RANK(AC17, $Y$3:$AC$29) -> 36 | AI17: =IF($P17>0, $O17/($P17+AI$2), 0) -> 0 | AJ17: =IF($P17>0, $O17/($P17+AJ$2), 0) -> 0 | AK17: =IF($P17>0, $O17/($P17+AK$2), 0) -> 0 | AL17: =IF($P17>0, $O17/($P17+AL$2), 0) -> 0 | AM17: =IF($P17>0, $O17/($P17+AM$2), 0) -> 0 | AN17: =IF($T18>0, $S18/($T18+AN$2), 0) -> 0 | AO17: =IF($T18>0, $S18/($T18+AO$2), 0) -> 0 | AP17: =IF($T18>0, $S18/($T18+AP$2), 0) -> 0 | AQ17: =IF($T18>0, $S18/($T18+AQ$2), 0) -> 0 | AR17: =IF($T18>0, $S18/($T18+AR$2), 0) -> 0 | AS17: =RANK(AI17, $AI17:$AR17) -> 1 | AT17: =RANK(AJ17, $AI17:$AR17) -> 1 | AU17: =RANK(AK17, $AI17:$AR17) -> 1 | AV17: =RANK(AL17, $AI17:$AR17) -> 1 | AW17: =RANK(AM17, $AI17:$AR17) -> 1 | AX17: =RANK(AN17, $AI17:$AR17) -> 1 | AY17: =RANK(AO17, $AI17:$AR17) -> 1 | AZ17: =RANK(AP17, $AI17:$AR17) -> 1 | ... BB17: =RANK(AR17, $AI17:$AR17) -> 1 | BE17: =RANK(BF17, $BF$17:BF$43) -> 3 | BF17: =Y3 -> 36248.778 | BG17: =BI3 -> ליכוד-ציונות דתית | BI17: חד"ש-תע"ל | BJ17: 2 | BK17: =BJ17&BI17 -> 2חד"ש-תע"ל | BL17: =if(BJ17=AS8, $BE8, IF(BJ17=AT8, $BE8, IF(BJ17=AX8, BF8, ""))) -> ום
A18: צ | B18: צעירים בוערים | C18: ='תוצאות'!C18 -> 8794 | D18: =E18+F18 -> 0 | E18: =ROUNDDOWN(H18,0) -> 0 | F18: =Q14 -> 0 | G18: =IF((C18/(SUM($C$3:C$41))>=$L$2), "כן", "לא") -> לא | H18: =IF(G18="כן", (C18/$K$2), 0) -> 0 | I18: =IF(G18="כן", $K$2*(E18+1)-C18, "") | N18: זנ | O18: =C22 -> 152 | P18: =E22 -> 0 | Q18: =COUNTIF(AS18:AW18,"<="&V18) -> 0 | U18: =COUNTIF(AX18:BB18,"<="&V18) -> 0 | V18: =COUNTIF(AD18:AH18,"<="&J$2) -> 0 | W18: =IF(P18>0, IF(T18>0, O18+S18, O18), IF(T18>0, S18, 0)) -> 0 | X18: =P18+T19 -> 0 | Y18: =IF(X18>0, $W18/($X18+Y$2), 0) -> 0 | Z18: =IF(Y18>0, $W18/($X18+Z$2), 0) -> 0 | AA18: =IF(Z18>0, $W18/($X18+AA$2), 0) -> 0 | AB18: =IF(AA18>0, $W18/($X18+AB$2), 0) -> 0 | AC18: =IF(AB18>0, $W18/($X18+AC$2), 0) -> 0 | AD18: =RANK(Y18, $Y$3:$AC$29) -> 36 | AE18: =RANK(Z18, $Y$3:$AC$29) -> 36 | AF18: =RANK(AA18, $Y$3:$AC$29) -> 36 | AG18: =RANK(AB18, $Y$3:$AC$29) -> 36 | AH18: =RANK(AC18, $Y$3:$AC$29) -> 36 | AI18: =IF($P18>0, $O18/($P18+AI$2), 0) -> 0 | AJ18: =IF($P18>0, $O18/($P18+AJ$2), 0) -> 0 | AK18: =IF($P18>0, $O18/($P18+AK$2), 0) -> 0 | AL18: =IF($P18>0, $O18/($P18+AL$2), 0) -> 0 | AM18: =IF($P18>0, $O18/($P18+AM$2), 0) -> 0 | AN18: =IF($T19>0, $S19/($T19+AN$2), 0) -> 0 | AO18: =IF($T19>0, $S19/($T19+AO$2), 0) -> 0 | AP18: =IF($T19>0, $S19/($T19+AP$2), 0) -> 0 | AQ18: =IF($T19>0, $S19/($T19+AQ$2), 0) -> 0 | AR18: =IF($T19>0, $S19/($T19+AR$2), 0) -> 0 | AS18: =RANK(AI18, $AI18:$AR18) -> 1 | AT18: =RANK(AJ18, $AI18:$AR18) -> 1 | AU18: =RANK(AK18, $AI18:$AR18) -> 1 | AV18: =RANK(AL18, $AI18:$AR18) -> 1 | AW18: =RANK(AM18, $AI18:$AR18) -> 1 | AX18: =RANK(AN18, $AI18:$AR18) -> 1 | AY18: =RANK(AO18, $AI18:$AR18) -> 1 | AZ18: =RANK(AP18, $AI18:$AR18) -> 1 | ... BB18: =RANK(AR18, $AI18:$AR18) -> 1 | BE18: =RANK(BF18, $BF$17:BF$43) -> 2 | BF18: =Y4 -> 36557.743 | BG18: =BI4 -> יש עתיד-המחנה הממלכתי | BI18: רע"ם | BJ18: 2 | BK18: =BJ18&BI18 -> 2רע"ם | BL18: =if(BJ18=AS9, $BE9, IF(BJ18=AT9, $BE9, IF(BJ18=AX9, BF9, ""))) -> עם
A19: אצ | B19: חופש כלכלי | C19: ='תוצאות'!C19 -> 15817 | D19: =E19+F19 -> 0 | E19: =ROUNDDOWN(H19,0) -> 0 | F19: =Q15 -> 0 | G19: =IF((C19/(SUM($C$3:C$41))>=$L$2), "כן", "לא") -> לא | H19: =IF(G19="כן", (C19/$K$2), 0) -> 0 | I19: =IF(G19="כן", $K$2*(E19+1)-C19, "") | N19: זץ | O19: =C23 -> 377 | P19: =E23 -> 0 | Q19: =COUNTIF(AS19:AW19,"<="&V19) -> 0 | U19: =COUNTIF(AX19:BB19,"<="&V19) -> 0 | V19: =COUNTIF(AD19:AH19,"<="&J$2) -> 0 | W19: =IF(P19>0, IF(T19>0, O19+S19, O19), IF(T19>0, S19, 0)) -> 0 | X19: =P19+T20 -> 0 | Y19: =IF(X19>0, $W19/($X19+Y$2), 0) -> 0 | Z19: =IF(Y19>0, $W19/($X19+Z$2), 0) -> 0 | AA19: =IF(Z19>0, $W19/($X19+AA$2), 0) -> 0 | AB19: =IF(AA19>0, $W19/($X19+AB$2), 0) -> 0 | AC19: =IF(AB19>0, $W19/($X19+AC$2), 0) -> 0 | AD19: =RANK(Y19, $Y$3:$AC$29) -> 36 | AE19: =RANK(Z19, $Y$3:$AC$29) -> 36 | AF19: =RANK(AA19, $Y$3:$AC$29) -> 36 | AG19: =RANK(AB19, $Y$3:$AC$29) -> 36 | AH19: =RANK(AC19, $Y$3:$AC$29) -> 36 | AI19: =IF($P19>0, $O19/($P19+AI$2), 0) -> 0 | AJ19: =IF($P19>0, $O19/($P19+AJ$2), 0) -> 0 | AK19: =IF($P19>0, $O19/($P19+AK$2), 0) -> 0 | AL19: =IF($P19>0, $O19/($P19+AL$2), 0) -> 0 | AM19: =IF($P19>0, $O19/($P19+AM$2), 0) -> 0 | AN19: =IF($T20>0, $S20/($T20+AN$2), 0) -> 0 | AO19: =IF($T20>0, $S20/($T20+AO$2), 0) -> 0 | AP19: =IF($T20>0, $S20/($T20+AP$2), 0) -> 0 | AQ19: =IF($T20>0, $S20/($T20+AQ$2), 0) -> 0 | AR19: =IF($T20>0, $S20/($T20+AR$2), 0) -> 0 | AS19: =RANK(AI19, $AI19:$AR19) -> 1 | AT19: =RANK(AJ19, $AI19:$AR19) -> 1 | AU19: =RANK(AK19, $AI19:$AR19) -> 1 | AV19: =RANK(AL19, $AI19:$AR19) -> 1 | AW19: =RANK(AM19, $AI19:$AR19) -> 1 | AX19: =RANK(AN19, $AI19:$AR19) -> 1 | AY19: =RANK(AO19, $AI19:$AR19) -> 1 | AZ19: =RANK(AP19, $AI19:$AR19) -> 1 | ... BB19: =RANK(AR19, $AI19:$AR19) -> 1 | BE19: =RANK(BF19, $BF$17:BF$43) -> 1 | BF19: =Y5 -> 37376.056 | BG19: =BI5 -> ש"ס-יהדות התורה | BI19: בל"ד | BJ19: 2 | BK19: =BJ19&BI19 -> 2בל"ד | BL19: =if(BJ19=AS10, $BE10, IF(BJ19=AT10, $BE10, IF(BJ19=AX10, BF10, "")))
A20: ז | B20: שחר כח חברתי | C20: ='תוצאות'!C20 -> 530 | D20: =E20+F20 -> 0 | E20: =ROUNDDOWN(H20,0) -> 0 | F20: =Q16 -> 0 | G20: =IF((C20/(SUM($C$3:C$41))>=$L$2), "כן", "לא") -> לא | H20: =IF(G20="כן", (C20/$K$2), 0) -> 0 | I20: =IF(G20="כן", $K$2*(E20+1)-C20, "") | N20: ינ | O20: =C24 -> 234 | P20: =E24 -> 0 | Q20: =COUNTIF(AS20:AW20,"<="&V20) -> 0 | U20: =COUNTIF(AX20:BB20,"<="&V20) -> 0 | V20: =COUNTIF(AD20:AH20,"<="&J$2) -> 0 | W20: =IF(P20>0, IF(T20>0, O20+S20, O20), IF(T20>0, S20, 0)) -> 0 | X20: =P20+T21 -> 0 | Y20: =IF(X20>0, $W20/($X20+Y$2), 0) -> 0 | Z20: =IF(Y20>0, $W20/($X20+Z$2), 0) -> 0 | AA20: =IF(Z20>0, $W20/($X20+AA$2), 0) -> 0 | AB20: =IF(AA20>0, $W20/($X20+AB$2), 0) -> 0 | AC20: =IF(AB20>0, $W20/($X20+AC$2), 0) -> 0 | AD20: =RANK(Y20, $Y$3:$AC$29) -> 36 | AE20: =RANK(Z20, $Y$3:$AC$29) -> 36 | AF20: =RANK(AA20, $Y$3:$AC$29) -> 36 | AG20: =RANK(AB20, $Y$3:$AC$29) -> 36 | AH20: =RANK(AC20, $Y$3:$AC$29) -> 36 | AI20: =IF($P20>0, $O20/($P20+AI$2), 0) -> 0 | AJ20: =IF($P20>0, $O20/($P20+AJ$2), 0) -> 0 | AK20: =IF($P20>0, $O20/($P20+AK$2), 0) -> 0 | AL20: =IF($P20>0, $O20/($P20+AL$2), 0) -> 0 | AM20: =IF($P20>0, $O20/($P20+AM$2), 0) -> 0 | AN20: =IF($T21>0, $S21/($T21+AN$2), 0) -> 0 | AO20: =IF($T21>0, $S21/($T21+AO$2), 0) -> 0 | AP20: =IF($T21>0, $S21/($T21+AP$2), 0) -> 0 | AQ20: =IF($T21>0, $S21/($T21+AQ$2), 0) -> 0 | AR20: =IF($T21>0, $S21/($T21+AR$2), 0) -> 0 | AS20: =RANK(AI20, $AI20:$AR20) -> 1 | AT20: =RANK(AJ20, $AI20:$AR20) -> 1 | AU20: =RANK(AK20, $AI20:$AR20) -> 1 | AV20: =RANK(AL20, $AI20:$AR20) -> 1 | AW20: =RANK(AM20, $AI20:$AR20) -> 1 | AX20: =RANK(AN20, $AI20:$AR20) -> 1 | AY20: =RANK(AO20, $AI20:$AR20) -> 1 | AZ20: =RANK(AP20, $AI20:$AR20) -> 1 | ... BB20: =RANK(AR20, $AI20:$AR20) -> 1 | BE20: =RANK(BF20, $BF$17:BF$43) -> 9 | BF20: =Y6 -> 35184.4 | BG20: =BI6 -> העבודה-מרצ | BI20: הבית היהודי | BJ20: 2 | BK20: =BJ20&BI20 -> 2הבית היהודי | BL20: =if(BJ20=AS11, $BE11, IF(BJ20=AT11, $BE11, IF(BJ20=AX11, BF11, "")))
A21: זך | B21: קמ"ה | C21: ='תוצאות'!C21 -> 205 | D21: =E21+F21 -> 0 | E21: =ROUNDDOWN(H21,0) -> 0 | F21: =Q17 -> 0 | G21: =IF((C21/(SUM($C$3:C$41))>=$L$2), "כן", "לא") -> לא | H21: =IF(G21="כן", (C21/$K$2), 0) -> 0 | I21: =IF(G21="כן", $K$2*(E21+1)-C21, "") | N21: יץ | O21: =C25 -> 265 | P21: =E25 -> 0 | Q21: =COUNTIF(AS21:AW21,"<="&V21) -> 0 | U21: =COUNTIF(AX21:BB21,"<="&V21) -> 0 | V21: =COUNTIF(AD21:AH21,"<="&J$2) -> 0 | W21: =IF(P21>0, IF(T21>0, O21+S21, O21), IF(T21>0, S21, 0)) -> 0 | X21: =P21+T22 -> 0 | Y21: =IF(X21>0, $W21/($X21+Y$2), 0) -> 0 | Z21: =IF(Y21>0, $W21/($X21+Z$2), 0) -> 0 | AA21: =IF(Z21>0, $W21/($X21+AA$2), 0) -> 0 | AB21: =IF(AA21>0, $W21/($X21+AB$2), 0) -> 0 | AC21: =IF(AB21>0, $W21/($X21+AC$2), 0) -> 0 | AD21: =RANK(Y21, $Y$3:$AC$29) -> 36 | AE21: =RANK(Z21, $Y$3:$AC$29) -> 36 | AF21: =RANK(AA21, $Y$3:$AC$29) -> 36 | AG21: =RANK(AB21, $Y$3:$AC$29) -> 36 | AH21: =RANK(AC21, $Y$3:$AC$29) -> 36 | AI21: =IF($P21>0, $O21/($P21+AI$2), 0) -> 0 | AJ21: =IF($P21>0, $O21/($P21+AJ$2), 0) -> 0 | AK21: =IF($P21>0, $O21/($P21+AK$2), 0) -> 0 | AL21: =IF($P21>0, $O21/($P21+AL$2), 0) -> 0 | AM21: =IF($P21>0, $O21/($P21+AM$2), 0) -> 0 | AN21: =IF($T22>0, $S22/($T22+AN$2), 0) -> 0 | AO21: =IF($T22>0, $S22/($T22+AO$2), 0) -> 0 | AP21: =IF($T22>0, $S22/($T22+AP$2), 0) -> 0 | AQ21: =IF($T22>0, $S22/($T22+AQ$2), 0) -> 0 | AR21: =IF($T22>0, $S22/($T22+AR$2), 0) -> 0 | AS21: =RANK(AI21, $AI21:$AR21) -> 1 | AT21: =RANK(AJ21, $AI21:$AR21) -> 1 | AU21: =RANK(AK21, $AI21:$AR21) -> 1 | AV21: =RANK(AL21, $AI21:$AR21) -> 1 | AW21: =RANK(AM21, $AI21:$AR21) -> 1 | AX21: =RANK(AN21, $AI21:$AR21) -> 1 | AY21: =RANK(AO21, $AI21:$AR21) -> 1 | AZ21: =RANK(AP21, $AI21:$AR21) -> 1 | ... BB21: =RANK(AR21, $AI21:$AR21) -> 1 | BE21: =RANK(BF21, $BF$17:BF$43) -> 5 | BF21: =Y7 -> 35609.167 | BG21: =BI7 -> ישראל ביתנו | BI21: ליכוד-ציונות דתית | BJ21: 3 | BK21: =BJ21&BI21 -> 3ליכוד-ציונות דתית | BL21: =if(BJ21=AS3, $BE3, IF(BJ21=AT3, $BE3, IF(BJ21=AX3, BF3, ""))) -> ט
